Workbook

Sheet Tabellone
A1: TABELLONE BOLLETTE - live | AB1: Aggiornato: | AD1: =Config!$B$2
A2: Per ogni scommessa: ✔ entrambe passano / ✖ no. Sfondo pieno = esito DEFINITIVO (verde vinta, rosso persa).
A4: BOLLETTA 1 (5.40€) | G4: BOLLETTA 2 (5.40€) | M4: BOLLETTA 3 (2.70€) | S4: BOLLETTA 4 (7.20€) | Y4: BOLLETTA 5 (16.20€) | AE4: BOLLETTA 6 (10.80€) | AK4: BOLLETTA 7 (10.80€) | AQ4: BOLLETTA 8 (2.70€) | AW4: BOLLETTA 9 (2.70€)
A5: Gir | B5: Coppia | C5: Q | D5: ✔ | G5: Gir | H5: Coppia | I5: Q | J5: ✔ | M5: Gir | N5: Coppia | O5: Q | P5: ✔ | S5: Gir | T5: Coppia | U5: Q | V5: ✔ | Y5: Gir | Z5: Coppia | AA5: Q | AB5: ✔ | AE5: Gir | AF5: Coppia | AG5: Q | AH5: ✔ | AK5: Gir | AL5: Coppia | AM5: Q | AN5: ✔ | AQ5: Gir | AR5: Coppia | AS5: Q | AT5: ✔ | AW5: Gir | AX5: Coppia | AY5: Q | AZ5: ✔
A6: =Scommesse!$C$2 | B6: =Scommesse!$D$2&" / "&Scommesse!$E$2 | C6: =Scommesse!$F$2 | D6: =IF(Scommesse!$S$2>0,"✔","") | E6: =Calcoli!$I$2 | G6: =Scommesse!$C$19 | H6: =Scommesse!$D$19&" / "&Scommesse!$E$19 | I6: =Scommesse!$F$19 | J6: =IF(Scommesse!$S$19>0,"✔","") | K6: =Calcoli!$I$12 | M6: =Scommesse!$C$36 | N6: =Scommesse!$D$36&" / "&Scommesse!$E$36 | O6: =Scommesse!$F$36 | P6: =IF(Scommesse!$S$36>0,"✔","") | Q6: =Calcoli!$I$22 | S6: =Scommesse!$C$51 | T6: =Scommesse!$D$51&" / "&Scommesse!$E$51 | U6: =Scommesse!$F$51 | V6: =IF(Scommesse!$S$51>0,"✔","") | W6: =Calcoli!$I$32 | Y6: =Scommesse!$C$67 | Z6: =Scommesse!$D$67&" / "&Scommesse!$E$67 | AA6: =Scommesse!$F$67 | AB6: =IF(Scommesse!$S$67>0,"✔","") | AC6: =Calcoli!$I$42 | AE6: =Scommesse!$C$84 | AF6: =Scommesse!$D$84&" / "&Scommesse!$E$84 | AG6: =Scommesse!$F$84 | AH6: =IF(Scommesse!$S$84>0,"✔","") | AI6: =Calcoli!$I$52 | AK6: =Scommesse!$C$101 | AL6: =Scommesse!$D$101&" / "&Scommesse!$E$101 | AM6: =Scommesse!$F$101 | AN6: =IF(Scommesse!$S$101>0,"✔","") | AO6: =Calcoli!$I$62 | AQ6: =Scommesse!$C$118 | AR6: =Scommesse!$D$118&" / "&Scommesse!$E$118 | AS6: =Scommesse!$F$118 | AT6: =IF(Scommesse!$S$118>0,"✔","") | AU6: =Calcoli!$I$72 | AW6: =Scommesse!$C$135 | AX6: =Scommesse!$D$135&" / "&Scommesse!$E$135 | AY6: =Scommesse!$F$135 | AZ6: =IF(Scommesse!$S$135>0,"✔","") | BA6: =Calcoli!$I$82
A7: =Scommesse!$C$3 | B7: =Scommesse!$D$3&" / "&Scommesse!$E$3 | C7: =Scommesse!$F$3 | D7: =IF(Scommesse!$S$3>0,"✔","") | E7: =Calcoli!$I$4 | G7: =Scommesse!$C$20 | H7: =Scommesse!$D$20&" / "&Scommesse!$E$20 | I7: =Scommesse!$F$20 | J7: =IF(Scommesse!$S$20>0,"✔","") | K7: =Calcoli!$I$14 | M7: =Scommesse!$C$37 | N7: =Scommesse!$D$37&" / "&Scommesse!$E$37 | O7: =Scommesse!$F$37 | P7: =IF(Scommesse!$S$37>0,"✔","") | Q7: =Calcoli!$I$24 | S7: =Scommesse!$C$52 | T7: =Scommesse!$D$52&" / "&Scommesse!$E$52 | U7: =Scommesse!$F$52 | V7: =IF(Scommesse!$S$52>0,"✔","") | W7: =Calcoli!$I$34 | Y7: =Scommesse!$C$68 | Z7: =Scommesse!$D$68&" / "&Scommesse!$E$68 | AA7: =Scommesse!$F$68 | AB7: =IF(Scommesse!$S$68>0,"✔","") | AC7: =Calcoli!$I$44 | AE7: =Scommesse!$C$85 | AF7: =Scommesse!$D$85&" / "&Scommesse!$E$85 | AG7: =Scommesse!$F$85 | AH7: =IF(Scommesse!$S$85>0,"✔","") | AI7: =Calcoli!$I$54 | AK7: =Scommesse!$C$102 | AL7: =Scommesse!$D$102&" / "&Scommesse!$E$102 | AM7: =Scommesse!$F$102 | AN7: =IF(Scommesse!$S$102>0,"✔","") | AO7: =Calcoli!$I$64 | AQ7: =Scommesse!$C$119 | AR7: =Scommesse!$D$119&" / "&Scommesse!$E$119 | AS7: =Scommesse!$F$119 | AT7: =IF(Scommesse!$S$119>0,"✔","") | AU7: =Calcoli!$I$74 | AW7: =Scommesse!$C$136 | AX7: =Scommesse!$D$136&" / "&Scommesse!$E$136 | AY7: =Scommesse!$F$136 | AZ7: =IF(Scommesse!$S$136>0,"✔","") | BA7: =Calcoli!$I$84
A8: =Scommesse!$C$4 | B8: =Scommesse!$D$4&" / "&Scommesse!$E$4 | C8: =Scommesse!$F$4 | D8: =IF(Scommesse!$S$4>0,"✔","") | E8: =Calcoli!$I$5 | G8: =Scommesse!$C$21 | H8: =Scommesse!$D$21&" / "&Scommesse!$E$21 | I8: =Scommesse!$F$21 | J8: =IF(Scommesse!$S$21>0,"✔","") | K8: =Calcoli!$I$15 | M8: =Scommesse!$C$38 | N8: =Scommesse!$D$38&" / "&Scommesse!$E$38 | O8: =Scommesse!$F$38 | P8: =IF(Scommesse!$S$38>0,"✔","") | Q8: =Calcoli!$I$25 | S8: =Scommesse!$C$53 | T8: =Scommesse!$D$53&" / "&Scommesse!$E$53 | U8: =Scommesse!$F$53 | V8: =IF(Scommesse!$S$53>0,"✔","") | W8: =Calcoli!$I$35 | Y8: =Scommesse!$C$69 | Z8: =Scommesse!$D$69&" / "&Scommesse!$E$69 | AA8: =Scommesse!$F$69 | AB8: =IF(Scommesse!$S$69>0,"✔","") | AC8: =Calcoli!$I$45 | AE8: =Scommesse!$C$86 | AF8: =Scommesse!$D$86&" / "&Scommesse!$E$86 | AG8: =Scommesse!$F$86 | AH8: =IF(Scommesse!$S$86>0,"✔","") | AI8: =Calcoli!$I$55 | AK8: =Scommesse!$C$103 | AL8: =Scommesse!$D$103&" / "&Scommesse!$E$103 | AM8: =Scommesse!$F$103 | AN8: =IF(Scommesse!$S$103>0,"✔","") | AO8: =Calcoli!$I$65 | AQ8: =Scommesse!$C$120 | AR8: =Scommesse!$D$120&" / "&Scommesse!$E$120 | AS8: =Scommesse!$F$120 | AT8: =IF(Scommesse!$S$120>0,"✔","") | AU8: =Calcoli!$I$75 | AW8: =Scommesse!$C$137 | AX8: =Scommesse!$D$137&" / "&Scommesse!$E$137 | AY8: =Scommesse!$F$137 | AZ8: =IF(Scommesse!$S$137>0,"✔","") | BA8: =Calcoli!$I$85
A9: =Scommesse!$C$5 | B9: =Scommesse!$D$5&" / "&Scommesse!$E$5 | C9: =Scommesse!$F$5 | D9: =IF(Scommesse!$S$5>0,"✔","") | E9: =Calcoli!$I$5 | G9: =Scommesse!$C$22 | H9: =Scommesse!$D$22&" / "&Scommesse!$E$22 | I9: =Scommesse!$F$22 | J9: =IF(Scommesse!$S$22>0,"✔","") | K9: =Calcoli!$I$15 | M9: =Scommesse!$C$39 | N9: =Scommesse!$D$39&" / "&Scommesse!$E$39 | O9: =Scommesse!$F$39 | P9: =IF(Scommesse!$S$39>0,"✔","") | Q9: =Calcoli!$I$25 | S9: =Scommesse!$C$54 | T9: =Scommesse!$D$54&" / "&Scommesse!$E$54 | U9: =Scommesse!$F$54 | V9: =IF(Scommesse!$S$54>0,"✔","") | W9: =Calcoli!$I$35 | Y9: =Scommesse!$C$70 | Z9: =Scommesse!$D$70&" / "&Scommesse!$E$70 | AA9: =Scommesse!$F$70 | AB9: =IF(Scommesse!$S$70>0,"✔","") | AC9: =Calcoli!$I$45 | AE9: =Scommesse!$C$87 | AF9: =Scommesse!$D$87&" / "&Scommesse!$E$87 | AG9: =Scommesse!$F$87 | AH9: =IF(Scommesse!$S$87>0,"✔","") | AI9: =Calcoli!$I$55 | AK9: =Scommesse!$C$104 | AL9: =Scommesse!$D$104&" / "&Scommesse!$E$104 | AM9: =Scommesse!$F$104 | AN9: =IF(Scommesse!$S$104>0,"✔","") | AO9: =Calcoli!$I$65 | AQ9: =Scommesse!$C$121 | AR9: =Scommesse!$D$121&" / "&Scommesse!$E$121 | AS9: =Scommesse!$F$121 | AT9: =IF(Scommesse!$S$121>0,"✔","") | AU9: =Calcoli!$I$75 | AW9: =Scommesse!$C$138 | AX9: =Scommesse!$D$138&" / "&Scommesse!$E$138 | AY9: =Scommesse!$F$138 | AZ9: =IF(Scommesse!$S$138>0,"✔","") | BA9: =Calcoli!$I$85
A10: =Scommesse!$C$6 | B10: =Scommesse!$D$6&" / "&Scommesse!$E$6 | C10: =Scommesse!$F$6 | D10: =IF(Scommesse!$S$6>0,"✔","") | E10: =Calcoli!$I$5 | G10: =Scommesse!$C$23 | H10: =Scommesse!$D$23&" / "&Scommesse!$E$23 | I10: =Scommesse!$F$23 | J10: =IF(Scommesse!$S$23>0,"✔","") | K10: =Calcoli!$I$15 | M10: =Scommesse!$C$40 | N10: =Scommesse!$D$40&" / "&Scommesse!$E$40 | O10: =Scommesse!$F$40 | P10: =IF(Scommesse!$S$40>0,"✔","") | Q10: =Calcoli!$I$25 | S10: =Scommesse!$C$55 | T10: =Scommesse!$D$55&" / "&Scommesse!$E$55 | U10: =Scommesse!$F$55 | V10: =IF(Scommesse!$S$55>0,"✔","") | W10: =Calcoli!$I$35 | Y10: =Scommesse!$C$71 | Z10: =Scommesse!$D$71&" / "&Scommesse!$E$71 | AA10: =Scommesse!$F$71 | AB10: =IF(Scommesse!$S$71>0,"✔","") | AC10: =Calcoli!$I$45 | AE10: =Scommesse!$C$88 | AF10: =Scommesse!$D$88&" / "&Scommesse!$E$88 | AG10: =Scommesse!$F$88 | AH10: =IF(Scommesse!$S$88>0,"✔","") | AI10: =Calcoli!$I$55 | AK10: =Scommesse!$C$105 | AL10: =Scommesse!$D$105&" / "&Scommesse!$E$105 | AM10: =Scommesse!$F$105 | AN10: =IF(Scommesse!$S$105>0,"✔","") | AO10: =Calcoli!$I$65 | AQ10: =Scommesse!$C$122 | AR10: =Scommesse!$D$122&" / "&Scommesse!$E$122 | AS10: =Scommesse!$F$122 | AT10: =IF(Scommesse!$S$122>0,"✔","") | AU10: =Calcoli!$I$75 | AW10: =Scommesse!$C$139 | AX10: =Scommesse!$D$139&" / "&Scommesse!$E$139 | AY10: =Scommesse!$F$139 | AZ10: =IF(Scommesse!$S$139>0,"✔","") | BA10: =Calcoli!$I$85
A11: =Scommesse!$C$7 | B11: =Scommesse!$D$7&" / "&Scommesse!$E$7 | C11: =Scommesse!$F$7 | D11: =IF(Scommesse!$S$7>0,"✔","") | E11: =Calcoli!$I$3 | G11: =Scommesse!$C$24 | H11: =Scommesse!$D$24&" / "&Scommesse!$E$24 | I11: =Scommesse!$F$24 | J11: =IF(Scommesse!$S$24>0,"✔","") | K11: =Calcoli!$I$13 | M11: =Scommesse!$C$41 | N11: =Scommesse!$D$41&" / "&Scommesse!$E$41 | O11: =Scommesse!$F$41 | P11: =IF(Scommesse!$S$41>0,"✔","") | Q11: =Calcoli!$I$23 | S11: =Scommesse!$C$56 | T11: =Scommesse!$D$56&" / "&Scommesse!$E$56 | U11: =Scommesse!$F$56 | V11: =IF(Scommesse!$S$56>0,"✔","") | W11: =Calcoli!$I$33 | Y11: =Scommesse!$C$72 | Z11: =Scommesse!$D$72&" / "&Scommesse!$E$72 | AA11: =Scommesse!$F$72 | AB11: =IF(Scommesse!$S$72>0,"✔","") | AC11: =Calcoli!$I$43 | AE11: =Scommesse!$C$89 | AF11: =Scommesse!$D$89&" / "&Scommesse!$E$89 | AG11: =Scommesse!$F$89 | AH11: =IF(Scommesse!$S$89>0,"✔","") | AI11: =Calcoli!$I$53 | AK11: =Scommesse!$C$106 | AL11: =Scommesse!$D$106&" / "&Scommesse!$E$106 | AM11: =Scommesse!$F$106 | AN11: =IF(Scommesse!$S$106>0,"✔","") | AO11: =Calcoli!$I$63 | AQ11: =Scommesse!$C$123 | AR11: =Scommesse!$D$123&" / "&Scommesse!$E$123 | AS11: =Scommesse!$F$123 | AT11: =IF(Scommesse!$S$123>0,"✔","") | AU11: =Calcoli!$I$73 | AW11: =Scommesse!$C$140 | AX11: =Scommesse!$D$140&" / "&Scommesse!$E$140 | AY11: =Scommesse!$F$140 | AZ11: =IF(Scommesse!$S$140>0,"✔","") | BA11: =Calcoli!$I$83
A12: =Scommesse!$C$8 | B12: =Scommesse!$D$8&" / "&Scommesse!$E$8 | C12: =Scommesse!$F$8 | D12: =IF(Scommesse!$S$8>0,"✔","") | E12: =Calcoli!$I$3 | G12: =Scommesse!$C$25 | H12: =Scommesse!$D$25&" / "&Scommesse!$E$25 | I12: =Scommesse!$F$25 | J12: =IF(Scommesse!$S$25>0,"✔","") | K12: =Calcoli!$I$13 | M12: =Scommesse!$C$42 | N12: =Scommesse!$D$42&" / "&Scommesse!$E$42 | O12: =Scommesse!$F$42 | P12: =IF(Scommesse!$S$42>0,"✔","") | Q12: =Calcoli!$I$23 | S12: =Scommesse!$C$57 | T12: =Scommesse!$D$57&" / "&Scommesse!$E$57 | U12: =Scommesse!$F$57 | V12: =IF(Scommesse!$S$57>0,"✔","") | W12: =Calcoli!$I$33 | Y12: =Scommesse!$C$73 | Z12: =Scommesse!$D$73&" / "&Scommesse!$E$73 | AA12: =Scommesse!$F$73 | AB12: =IF(Scommesse!$S$73>0,"✔","") | AC12: =Calcoli!$I$43 | AE12: =Scommesse!$C$90 | AF12: =Scommesse!$D$90&" / "&Scommesse!$E$90 | AG12: =Scommesse!$F$90 | AH12: =IF(Scommesse!$S$90>0,"✔","") | AI12: =Calcoli!$I$53 | AK12: =Scommesse!$C$107 | AL12: =Scommesse!$D$107&" / "&Scommesse!$E$107 | AM12: =Scommesse!$F$107 | AN12: =IF(Scommesse!$S$107>0,"✔","") | AO12: =Calcoli!$I$63 | AQ12: =Scommesse!$C$124 | AR12: =Scommesse!$D$124&" / "&Scommesse!$E$124 | AS12: =Scommesse!$F$124 | AT12: =IF(Scommesse!$S$124>0,"✔","") | AU12: =Calcoli!$I$73 | AW12: =Scommesse!$C$141 | AX12: =Scommesse!$D$141&" / "&Scommesse!$E$141 | AY12: =Scommesse!$F$141 | AZ12: =IF(Scommesse!$S$141>0,"✔","") | BA12: =Calcoli!$I$83
A13: =Scommesse!$C$9 | B13: =Scommesse!$D$9&" / "&Scommesse!$E$9 | C13: =Scommesse!$F$9 | D13: =IF(Scommesse!$S$9>0,"✔","") | E13: =Calcoli!$I$3 | G13: =Scommesse!$C$26 | H13: =Scommesse!$D$26&" / "&Scommesse!$E$26 | I13: =Scommesse!$F$26 | J13: =IF(Scommesse!$S$26>0,"✔","") | K13: =Calcoli!$I$13 | M13: =Scommesse!$C$43 | N13: =Scommesse!$D$43&" / "&Scommesse!$E$43 | O13: =Scommesse!$F$43 | P13: =IF(Scommesse!$S$43>0,"✔","") | Q13: =Calcoli!$I$23 | S13: =Scommesse!$C$58 | T13: =Scommesse!$D$58&" / "&Scommesse!$E$58 | U13: =Scommesse!$F$58 | V13: =IF(Scommesse!$S$58>0,"✔","") | W13: =Calcoli!$I$33 | Y13: =Scommesse!$C$74 | Z13: =Scommesse!$D$74&" / "&Scommesse!$E$74 | AA13: =Scommesse!$F$74 | AB13: =IF(Scommesse!$S$74>0,"✔","") | AC13: =Calcoli!$I$43 | AE13: =Scommesse!$C$91 | AF13: =Scommesse!$D$91&" / "&Scommesse!$E$91 | AG13: =Scommesse!$F$91 | AH13: =IF(Scommesse!$S$91>0,"✔","") | AI13: =Calcoli!$I$53 | AK13: =Scommesse!$C$108 | AL13: =Scommesse!$D$108&" / "&Scommesse!$E$108 | AM13: =Scommesse!$F$108 | AN13: =IF(Scommesse!$S$108>0,"✔","") | AO13: =Calcoli!$I$63 | AQ13: =Scommesse!$C$125 | AR13: =Scommesse!$D$125&" / "&Scommesse!$E$125 | AS13: =Scommesse!$F$125 | AT13: =IF(Scommesse!$S$125>0,"✔","") | AU13: =Calcoli!$I$73 | AW13: =Scommesse!$C$142 | AX13: =Scommesse!$D$142&" / "&Scommesse!$E$142 | AY13: =Scommesse!$F$142 | AZ13: =IF(Scommesse!$S$142>0,"✔","") | BA13: =Calcoli!$I$83
A14: =Scommesse!$C$10 | B14: =Scommesse!$D$10&" / "&Scommesse!$E$10 | C14: =Scommesse!$F$10 | D14: =IF(Scommesse!$S$10>0,"✔","") | E14: =Calcoli!$I$8 | G14: =Scommesse!$C$27 | H14: =Scommesse!$D$27&" / "&Scommesse!$E$27 | I14: =Scommesse!$F$27 | J14: =IF(Scommesse!$S$27>0,"✔","") | K14: =Calcoli!$I$18 | M14: =Scommesse!$C$44 | N14: =Scommesse!$D$44&" / "&Scommesse!$E$44 | O14: =Scommesse!$F$44 | P14: =IF(Scommesse!$S$44>0,"✔","") | Q14: =Calcoli!$I$28 | S14: =Scommesse!$C$59 | T14: =Scommesse!$D$59&" / "&Scommesse!$E$59 | U14: =Scommesse!$F$59 | V14: =IF(Scommesse!$S$59>0,"✔","") | W14: =Calcoli!$I$38 | Y14: =Scommesse!$C$75 | Z14: =Scommesse!$D$75&" / "&Scommesse!$E$75 | AA14: =Scommesse!$F$75 | AB14: =IF(Scommesse!$S$75>0,"✔","") | AC14: =Calcoli!$I$48 | AE14: =Scommesse!$C$92 | AF14: =Scommesse!$D$92&" / "&Scommesse!$E$92 | AG14: =Scommesse!$F$92 | AH14: =IF(Scommesse!$S$92>0,"✔","") | AI14: =Calcoli!$I$58 | AK14: =Scommesse!$C$109 | AL14: =Scommesse!$D$109&" / "&Scommesse!$E$109 | AM14: =Scommesse!$F$109 | AN14: =IF(Scommesse!$S$109>0,"✔","") | AO14: =Calcoli!$I$68 | AQ14: =Scommesse!$C$126 | AR14: =Scommesse!$D$126&" / "&Scommesse!$E$126 | AS14: =Scommesse!$F$126 | AT14: =IF(Scommesse!$S$126>0,"✔","") | AU14: =Calcoli!$I$78 | AW14: =Scommesse!$C$143 | AX14: =Scommesse!$D$143&" / "&Scommesse!$E$143 | AY14: =Scommesse!$F$143 | AZ14: =IF(Scommesse!$S$143>0,"✔","") | BA14: =Calcoli!$I$88
A15: =Scommesse!$C$11 | B15: =Scommesse!$D$11&" / "&Scommesse!$E$11 | C15: =Scommesse!$F$11 | D15: =IF(Scommesse!$S$11>0,"✔","") | E15: =Calcoli!$I$7 | G15: =Scommesse!$C$28 | H15: =Scommesse!$D$28&" / "&Scommesse!$E$28 | I15: =Scommesse!$F$28 | J15: =IF(Scommesse!$S$28>0,"✔","") | K15: =Calcoli!$I$17 | M15: =Scommesse!$C$45 | N15: =Scommesse!$D$45&" / "&Scommesse!$E$45 | O15: =Scommesse!$F$45 | P15: =IF(Scommesse!$S$45>0,"✔","") | Q15: =Calcoli!$I$27 | S15: =Scommesse!$C$60 | T15: =Scommesse!$D$60&" / "&Scommesse!$E$60 | U15: =Scommesse!$F$60 | V15: =IF(Scommesse!$S$60>0,"✔","") | W15: =Calcoli!$I$37 | Y15: =Scommesse!$C$76 | Z15: =Scommesse!$D$76&" / "&Scommesse!$E$76 | AA15: =Scommesse!$F$76 | AB15: =IF(Scommesse!$S$76>0,"✔","") | AC15: =Calcoli!$I$47 | AE15: =Scommesse!$C$93 | AF15: =Scommesse!$D$93&" / "&Scommesse!$E$93 | AG15: =Scommesse!$F$93 | AH15: =IF(Scommesse!$S$93>0,"✔","") | AI15: =Calcoli!$I$57 | AK15: =Scommesse!$C$110 | AL15: =Scommesse!$D$110&" / "&Scommesse!$E$110 | AM15: =Scommesse!$F$110 | AN15: =IF(Scommesse!$S$110>0,"✔","") | AO15: =Calcoli!$I$67 | AQ15: =Scommesse!$C$127 | AR15: =Scommesse!$D$127&" / "&Scommesse!$E$127 | AS15: =Scommesse!$F$127 | AT15: =IF(Scommesse!$S$127>0,"✔","") | AU15: =Calcoli!$I$77 | AW15: =Scommesse!$C$144 | AX15: =Scommesse!$D$144&" / "&Scommesse!$E$144 | AY15: =Scommesse!$F$144 | AZ15: =IF(Scommesse!$S$144>0,"✔","") | BA15: =Calcoli!$I$87
A16: =Scommesse!$C$12 | B16: =Scommesse!$D$12&" / "&Scommesse!$E$12 | C16: =Scommesse!$F$12 | D16: =IF(Scommesse!$S$12>0,"✔","") | E16: =Calcoli!$I$6 | G16: =Scommesse!$C$29 | H16: =Scommesse!$D$29&" / "&Scommesse!$E$29 | I16: =Scommesse!$F$29 | J16: =IF(Scommesse!$S$29>0,"✔","") | K16: =Calcoli!$I$16 | M16: =Scommesse!$C$46 | N16: =Scommesse!$D$46&" / "&Scommesse!$E$46 | O16: =Scommesse!$F$46 | P16: =IF(Scommesse!$S$46>0,"✔","") | Q16: =Calcoli!$I$26 | S16: =Scommesse!$C$61 | T16: =Scommesse!$D$61&" / "&Scommesse!$E$61 | U16: =Scommesse!$F$61 | V16: =IF(Scommesse!$S$61>0,"✔","") | W16: =Calcoli!$I$36 | Y16: =Scommesse!$C$77 | Z16: =Scommesse!$D$77&" / "&Scommesse!$E$77 | AA16: =Scommesse!$F$77 | AB16: =IF(Scommesse!$S$77>0,"✔","") | AC16: =Calcoli!$I$46 | AE16: =Scommesse!$C$94 | AF16: =Scommesse!$D$94&" / "&Scommesse!$E$94 | AG16: =Scommesse!$F$94 | AH16: =IF(Scommesse!$S$94>0,"✔","") | AI16: =Calcoli!$I$56 | AK16: =Scommesse!$C$111 | AL16: =Scommesse!$D$111&" / "&Scommesse!$E$111 | AM16: =Scommesse!$F$111 | AN16: =IF(Scommesse!$S$111>0,"✔","") | AO16: =Calcoli!$I$66 | AQ16: =Scommesse!$C$128 | AR16: =Scommesse!$D$128&" / "&Scommesse!$E$128 | AS16: =Scommesse!$F$128 | AT16: =IF(Scommesse!$S$128>0,"✔","") | AU16: =Calcoli!$I$76 | AW16: =Scommesse!$C$145 | AX16: =Scommesse!$D$145&" / "&Scommesse!$E$145 | AY16: =Scommesse!$F$145 | AZ16: =IF(Scommesse!$S$145>0,"✔","") | BA16: =Calcoli!$I$86
A17: =Scommesse!$C$13 | B17: =Scommesse!$D$13&" / "&Scommesse!$E$13 | C17: =Scommesse!$F$13 | D17: =IF(Scommesse!$S$13>0,"✔","") | E17: =Calcoli!$I$6 | G17: =Scommesse!$C$30 | H17: =Scommesse!$D$30&" / "&Scommesse!$E$30 | I17: =Scommesse!$F$30 | J17: =IF(Scommesse!$S$30>0,"✔","") | K17: =Calcoli!$I$16 | M17: =Scommesse!$C$47 | N17: =Scommesse!$D$47&" / "&Scommesse!$E$47 | O17: =Scommesse!$F$47 | P17: =IF(Scommesse!$S$47>0,"✔","") | Q17: =Calcoli!$I$31 | S17: =Scommesse!$C$62 | T17: =Scommesse!$D$62&" / "&Scommesse!$E$62 | U17: =Scommesse!$F$62 | V17: =IF(Scommesse!$S$62>0,"✔","") | W17: =Calcoli!$I$36 | Y17: =Scommesse!$C$78 | Z17: =Scommesse!$D$78&" / "&Scommesse!$E$78 | AA17: =Scommesse!$F$78 | AB17: =IF(Scommesse!$S$78>0,"✔","") | AC17: =Calcoli!$I$46 | AE17: =Scommesse!$C$95 | AF17: =Scommesse!$D$95&" / "&Scommesse!$E$95 | AG17: =Scommesse!$F$95 | AH17: =IF(Scommesse!$S$95>0,"✔","") | AI17: =Calcoli!$I$56 | AK17: =Scommesse!$C$112 | AL17: =Scommesse!$D$112&" / "&Scommesse!$E$112 | AM17: =Scommesse!$F$112 | AN17: =IF(Scommesse!$S$112>0,"✔","") | AO17: =Calcoli!$I$66 | AQ17: =Scommesse!$C$129 | AR17: =Scommesse!$D$129&" / "&Scommesse!$E$129 | AS17: =Scommesse!$F$129 | AT17: =IF(Scommesse!$S$129>0,"✔","") | AU17: =Calcoli!$I$76 | AW17: =Scommesse!$C$146 | AX17: =Scommesse!$D$146&" / "&Scommesse!$E$146 | AY17: =Scommesse!$F$146 | AZ17: =IF(Scommesse!$S$146>0,"✔","") | BA17: =Calcoli!$I$86
A18: =Scommesse!$C$14 | B18: =Scommesse!$D$14&" / "&Scommesse!$E$14 | C18: =Scommesse!$F$14 | D18: =IF(Scommesse!$S$14>0,"✔","") | E18: =Calcoli!$I$6 | G18: =Scommesse!$C$31 | H18: =Scommesse!$D$31&" / "&Scommesse!$E$31 | I18: =Scommesse!$F$31 | J18: =IF(Scommesse!$S$31>0,"✔","") | K18: =Calcoli!$I$16 | M18: =Scommesse!$C$48 | N18: =Scommesse!$D$48&" / "&Scommesse!$E$48 | O18: =Scommesse!$F$48 | P18: =IF(Scommesse!$S$48>0,"✔","") | Q18: =Calcoli!$I$30 | S18: =Scommesse!$C$63 | T18: =Scommesse!$D$63&" / "&Scommesse!$E$63 | U18: =Scommesse!$F$63 | V18: =IF(Scommesse!$S$63>0,"✔","") | W18: =Calcoli!$I$41 | Y18: =Scommesse!$C$79 | Z18: =Scommesse!$D$79&" / "&Scommesse!$E$79 | AA18: =Scommesse!$F$79 | AB18: =IF(Scommesse!$S$79>0,"✔","") | AC18: =Calcoli!$I$46 | AE18: =Scommesse!$C$96 | AF18: =Scommesse!$D$96&" / "&Scommesse!$E$96 | AG18: =Scommesse!$F$96 | AH18: =IF(Scommesse!$S$96>0,"✔","") | AI18: =Calcoli!$I$56 | AK18: =Scommesse!$C$113 | AL18: =Scommesse!$D$113&" / "&Scommesse!$E$113 | AM18: =Scommesse!$F$113 | AN18: =IF(Scommesse!$S$113>0,"✔","") | AO18: =Calcoli!$I$66 | AQ18: =Scommesse!$C$130 | AR18: =Scommesse!$D$130&" / "&Scommesse!$E$130 | AS18: =Scommesse!$F$130 | AT18: =IF(Scommesse!$S$130>0,"✔","") | AU18: =Calcoli!$I$76 | AW18: =Scommesse!$C$147 | AX18: =Scommesse!$D$147&" / "&Scommesse!$E$147 | AY18: =Scommesse!$F$147 | AZ18: =IF(Scommesse!$S$147>0,"✔","") | BA18: =Calcoli!$I$86
A19: =Scommesse!$C$15 | B19: =Scommesse!$D$15&" / "&Scommesse!$E$15 | C19: =Scommesse!$F$15 | D19: =IF(Scommesse!$S$15>0,"✔","") | E19: =Calcoli!$I$11 | G19: =Scommesse!$C$32 | H19: =Scommesse!$D$32&" / "&Scommesse!$E$32 | I19: =Scommesse!$F$32 | J19: =IF(Scommesse!$S$32>0,"✔","") | K19: =Calcoli!$I$21 | M19: =Scommesse!$C$49 | N19: =Scommesse!$D$49&" / "&Scommesse!$E$49 | O19: =Scommesse!$F$49 | P19: =IF(Scommesse!$S$49>0,"✔","") | Q19: =Calcoli!$I$30 | S19: =Scommesse!$C$64 | T19: =Scommesse!$D$64&" / "&Scommesse!$E$64 | U19: =Scommesse!$F$64 | V19: =IF(Scommesse!$S$64>0,"✔","") | W19: =Calcoli!$I$40 | Y19: =Scommesse!$C$80 | Z19: =Scommesse!$D$80&" / "&Scommesse!$E$80 | AA19: =Scommesse!$F$80 | AB19: =IF(Scommesse!$S$80>0,"✔","") | AC19: =Calcoli!$I$51 | AE19: =Scommesse!$C$97 | AF19: =Scommesse!$D$97&" / "&Scommesse!$E$97 | AG19: =Scommesse!$F$97 | AH19: =IF(Scommesse!$S$97>0,"✔","") | AI19: =Calcoli!$I$61 | AK19: =Scommesse!$C$114 | AL19: =Scommesse!$D$114&" / "&Scommesse!$E$114 | AM19: =Scommesse!$F$114 | AN19: =IF(Scommesse!$S$114>0,"✔","") | AO19: =Calcoli!$I$71 | AQ19: =Scommesse!$C$131 | AR19: =Scommesse!$D$131&" / "&Scommesse!$E$131 | AS19: =Scommesse!$F$131 | AT19: =IF(Scommesse!$S$131>0,"✔","") | AU19: =Calcoli!$I$81 | AW19: =Scommesse!$C$148 | AX19: =Scommesse!$D$148&" / "&Scommesse!$E$148 | AY19: =Scommesse!$F$148 | AZ19: =IF(Scommesse!$S$148>0,"✔","") | BA19: =Calcoli!$I$91
A20: =Scommesse!$C$16 | B20: =Scommesse!$D$16&" / "&Scommesse!$E$16 | C20: =Scommesse!$F$16 | D20: =IF(Scommesse!$S$16>0,"✔","") | E20: =Calcoli!$I$10 | G20: =Scommesse!$C$33 | H20: =Scommesse!$D$33&" / "&Scommesse!$E$33 | I20: =Scommesse!$F$33 | J20: =IF(Scommesse!$S$33>0,"✔","") | K20: =Calcoli!$I$20 | M20: =Scommesse!$C$50 | N20: =Scommesse!$D$50&" / "&Scommesse!$E$50 | O20: =Scommesse!$F$50 | P20: =IF(Scommesse!$S$50>0,"✔","") | Q20: =Calcoli!$I$29 | S20: =Scommesse!$C$65 | T20: =Scommesse!$D$65&" / "&Scommesse!$E$65 | U20: =Scommesse!$F$65 | V20: =IF(Scommesse!$S$65>0,"✔","") | W20: =Calcoli!$I$40 | Y20: =Scommesse!$C$81 | Z20: =Scommesse!$D$81&" / "&Scommesse!$E$81 | AA20: =Scommesse!$F$81 | AB20: =IF(Scommesse!$S$81>0,"✔","") | AC20: =Calcoli!$I$50 | AE20: =Scommesse!$C$98 | AF20: =Scommesse!$D$98&" / "&Scommesse!$E$98 | AG20: =Scommesse!$F$98 | AH20: =IF(Scommesse!$S$98>0,"✔","") | AI20: =Calcoli!$I$60 | AK20: =Scommesse!$C$115 | AL20: =Scommesse!$D$115&" / "&Scommesse!$E$115 | AM20: =Scommesse!$F$115 | AN20: =IF(Scommesse!$S$115>0,"✔","") | AO20: =Calcoli!$I$70 | AQ20: =Scommesse!$C$132 | AR20: =Scommesse!$D$132&" / "&Scommesse!$E$132 | AS20: =Scommesse!$F$132 | AT20: =IF(Scommesse!$S$132>0,"✔","") | AU20: =Calcoli!$I$80 | AW20: =Scommesse!$C$149 | AX20: =Scommesse!$D$149&" / "&Scommesse!$E$149 | AY20: =Scommesse!$F$149 | AZ20: =IF(Scommesse!$S$149>0,"✔","") | BA20: =Calcoli!$I$90
A21: =Scommesse!$C$17 | B21: =Scommesse!$D$17&" / "&Scommesse!$E$17 | C21: =Scommesse!$F$17 | D21: =IF(Scommesse!$S$17>0,"✔","") | E21: =Calcoli!$I$10 | G21: =Scommesse!$C$34 | H21: =Scommesse!$D$34&" / "&Scommesse!$E$34 | I21: =Scommesse!$F$34 | J21: =IF(Scommesse!$S$34>0,"✔","") | K21: =Calcoli!$I$20 | S21: =Scommesse!$C$66 | T21: =Scommesse!$D$66&" / "&Scommesse!$E$66 | U21: =Scommesse!$F$66 | V21: =IF(Scommesse!$S$66>0,"✔","") | W21: =Calcoli!$I$39 | Y21: =Scommesse!$C$82 | Z21: =Scommesse!$D$82&" / "&Scommesse!$E$82 | AA21: =Scommesse!$F$82 | AB21: =IF(Scommesse!$S$82>0,"✔","") | AC21: =Calcoli!$I$50 | AE21: =Scommesse!$C$99 | AF21: =Scommesse!$D$99&" / "&Scommesse!$E$99 | AG21: =Scommesse!$F$99 | AH21: =IF(Scommesse!$S$99>0,"✔","") | AI21: =Calcoli!$I$60 | AK21: =Scommesse!$C$116 | AL21: =Scommesse!$D$116&" / "&Scommesse!$E$116 | AM21: =Scommesse!$F$116 | AN21: =IF(Scommesse!$S$116>0,"✔","") | AO21: =Calcoli!$I$70 | AQ21: =Scommesse!$C$133 | AR21: =Scommesse!$D$133&" / "&Scommesse!$E$133 | AS21: =Scommesse!$F$133 | AT21: =IF(Scommesse!$S$133>0,"✔","") | AU21: =Calcoli!$I$80 | AW21: =Scommesse!$C$150 | AX21: =Scommesse!$D$150&" / "&Scommesse!$E$150 | AY21: =Scommesse!$F$150 | AZ21: =IF(Scommesse!$S$150>0,"✔","") | BA21: =Calcoli!$I$90
A22: =Scommesse!$C$18 | B22: =Scommesse!$D$18&" / "&Scommesse!$E$18 | C22: =Scommesse!$F$18 | D22: =IF(Scommesse!$S$18>0,"✔","") | E22: =Calcoli!$I$9 | G22: =Scommesse!$C$35 | H22: =Scommesse!$D$35&" / "&Scommesse!$E$35 | I22: =Scommesse!$F$35 | J22: =IF(Scommesse!$S$35>0,"✔","") | K22: =Calcoli!$I$19 | Y22: =Scommesse!$C$83 | Z22: =Scommesse!$D$83&" / "&Scommesse!$E$83 | AA22: =Scommesse!$F$83 | AB22: =IF(Scommesse!$S$83>0,"✔","") | AC22: =Calcoli!$I$49 | AE22: =Scommesse!$C$100 | AF22: =Scommesse!$D$100&" / "&Scommesse!$E$100 | AG22: =Scommesse!$F$100 | AH22: =IF(Scommesse!$S$100>0,"✔","") | AI22: =Calcoli!$I$59 | AK22: =Scommesse!$C$117 | AL22: =Scommesse!$D$117&" / "&Scommesse!$E$117 | AM22: =Scommesse!$F$117 | AN22: =IF(Scommesse!$S$117>0,"✔","") | AO22: =Calcoli!$I$69 | AQ22: =Scommesse!$C$134 | AR22: =Scommesse!$D$134&" / "&Scommesse!$E$134 | AS22: =Scommesse!$F$134 | AT22: =IF(Scommesse!$S$134>0,"✔","") | AU22: =Calcoli!$I$79 | AW22: =Scommesse!$C$151 | AX22: =Scommesse!$D$151&" / "&Scommesse!$E$151 | AY22: =Scommesse!$F$151 | AZ22: =IF(Scommesse!$S$151>0,"✔","") | BA22: =Calcoli!$I$89
A23: =IF(Riepilogo!$O$4>0,"✔ ","✖ ")&"Attuale "&TEXT(0.10*EXP(SUMPRODUCT((Scommesse!$A$2:$A$151=1)*(Scommesse!$Q$2:$Q$151)*LN(Scommesse!$F$2:$F$151))),"#,##0.00")&" €" | E23: =Riepilogo!$O$4 | G23: =IF(Riepilogo!$O$5>0,"✔ ","✖ ")&"Attuale "&TEXT(0.10*EXP(SUMPRODUCT((Scommesse!$A$2:$A$151=2)*(Scommesse!$Q$2:$Q$151)*LN(Scommesse!$F$2:$F$151))),"#,##0.00")&" €" | K23: =Riepilogo!$O$5 | M23: =IF(Riepilogo!$O$6>0,"✔ ","✖ ")&"Attuale "&TEXT(0.15*EXP(SUMPRODUCT((Scommesse!$A$2:$A$151=3)*(Scommesse!$Q$2:$Q$151)*LN(Scommesse!$F$2:$F$151))),"#,##0.00")&" €" | Q23: =Riepilogo!$O$6 | S23: =IF(Riepilogo!$O$7>0,"✔ ","✖ ")&"Attuale "&TEXT(0.20*EXP(SUMPRODUCT((Scommesse!$A$2:$A$151=4)*(Scommesse!$Q$2:$Q$151)*LN(Scommesse!$F$2:$F$151))),"#,##0.00")&" €" | W23: =Riepilogo!$O$7 | Y23: =IF(Riepilogo!$O$8>0,"✔ ","✖ ")&"Attuale "&TEXT(0.30*EXP(SUMPRODUCT((Scommesse!$A$2:$A$151=5)*(Scommesse!$Q$2:$Q$151)*LN(Scommesse!$F$2:$F$151))),"#,##0.00")&" €" | AC23: =Riepilogo!$O$8 | AE23: =IF(Riepilogo!$O$9>0,"✔ ","✖ ")&"Attuale "&TEXT(0.20*EXP(SUMPRODUCT((Scommesse!$A$2:$A$151=6)*(Scommesse!$Q$2:$Q$151)*LN(Scommesse!$F$2:$F$151))),"#,##0.00")&" €" | AI23: =Riepilogo!$O$9 | AK23: =IF(Riepilogo!$O$10>0,"✔ ","✖ ")&"Attuale "&TEXT(0.20*EXP(SUMPRODUCT((Scommesse!$A$2:$A$151=7)*(Scommesse!$Q$2:$Q$151)*LN(Scommesse!$F$2:$F$151))),"#,##0.00")&" €" | AO23: =Riepilogo!$O$10 | AQ23: =IF(Riepilogo!$O$11>0,"✔ ","✖ ")&"Attuale "&TEXT(0.05*EXP(SUMPRODUCT((Scommesse!$A$2:$A$151=8)*(Scommesse!$Q$2:$Q$151)*LN(Scommesse!$F$2:$F$151))),"#,##0.00")&" €" | AU23: =Riepilogo!$O$11 | AW23: =IF(Riepilogo!$O$12>0,"✔ ","✖ ")&"Attuale "&TEXT(0.05*EXP(SUMPRODUCT((Scommesse!$A$2:$A$151=9)*(Scommesse!$Q$2:$Q$151)*LN(Scommesse!$F$2:$F$151))),"#,##0.00")&" €" | BA23: =Riepilogo!$O$12

Sheet Gironi
A1: GIRONI - Classifiche live | N1: Aggiornato: | P1: =Config!$B$2
A2: Verde = situazione OK per le scommesse (✅ tra i primi 2 / ⛔ fuori dai primi 2). Rosa = situazione sfavorevole. Rim = partite da giocare.
A4: GIRONE A | G4: GIRONE B | M4: GIRONE C | S4: GIRONE D | Y4: GIRONE E | AE4: GIRONE F
A5: Pos | B5: Squadra | C5: Pti | D5: Rim | G5: Pos | H5: Squadra | I5: Pti | J5: Rim | M5: Pos | N5: Squadra | O5: Pti | P5: Rim | S5: Pos | T5: Squadra | U5: Pti | V5: Rim | Y5: Pos | Z5: Squadra | AA5: Pti | AB5: Rim | AE5: Pos | AF5: Squadra | AG5: Pti | AH5: Rim
A6: 1 | B6: =IFERROR(INDEX(Classifiche!$B$4:$B$51,MATCH(1,(Classifiche!$A$4:$A$51="A")*(Classifiche!$L$4:$L$51=1),0)),"") | C6: =IFERROR(INDEX(Classifiche!$I$4:$I$51,MATCH(1,(Classifiche!$A$4:$A$51="A")*(Classifiche!$L$4:$L$51=1),0)),"") | D6: =IFERROR(INDEX(Classifiche!$AA$4:$AA$51,MATCH(1,(Classifiche!$A$4:$A$51="A")*(Classifiche!$L$4:$L$51=1),0)),"") | E6: =IFERROR(INDEX(Classifiche!$AB$4:$AB$51,MATCH(1,(Classifiche!$A$4:$A$51="A")*(Classifiche!$L$4:$L$51=1),0)),"") | G6: 1 | H6: =IFERROR(INDEX(Classifiche!$B$4:$B$51,MATCH(1,(Classifiche!$A$4:$A$51="B")*(Classifiche!$L$4:$L$51=1),0)),"") | I6: =IFERROR(INDEX(Classifiche!$I$4:$I$51,MATCH(1,(Classifiche!$A$4:$A$51="B")*(Classifiche!$L$4:$L$51=1),0)),"") | J6: =IFERROR(INDEX(Classifiche!$AA$4:$AA$51,MATCH(1,(Classifiche!$A$4:$A$51="B")*(Classifiche!$L$4:$L$51=1),0)),"") | K6: =IFERROR(INDEX(Classifiche!$AB$4:$AB$51,MATCH(1,(Classifiche!$A$4:$A$51="B")*(Classifiche!$L$4:$L$51=1),0)),"") | M6: 1 | N6: =IFERROR(INDEX(Classifiche!$B$4:$B$51,MATCH(1,(Classifiche!$A$4:$A$51="C")*(Classifiche!$L$4:$L$51=1),0)),"") | O6: =IFERROR(INDEX(Classifiche!$I$4:$I$51,MATCH(1,(Classifiche!$A$4:$A$51="C")*(Classifiche!$L$4:$L$51=1),0)),"") | P6: =IFERROR(INDEX(Classifiche!$AA$4:$AA$51,MATCH(1,(Classifiche!$A$4:$A$51="C")*(Classifiche!$L$4:$L$51=1),0)),"") | Q6: =IFERROR(INDEX(Classifiche!$AB$4:$AB$51,MATCH(1,(Classifiche!$A$4:$A$51="C")*(Classifiche!$L$4:$L$51=1),0)),"") | S6: 1 | T6: =IFERROR(INDEX(Classifiche!$B$4:$B$51,MATCH(1,(Classifiche!$A$4:$A$51="D")*(Classifiche!$L$4:$L$51=1),0)),"") | U6: =IFERROR(INDEX(Classifiche!$I$4:$I$51,MATCH(1,(Classifiche!$A$4:$A$51="D")*(Classifiche!$L$4:$L$51=1),0)),"") | V6: =IFERROR(INDEX(Classifiche!$AA$4:$AA$51,MATCH(1,(Classifiche!$A$4:$A$51="D")*(Classifiche!$L$4:$L$51=1),0)),"") | W6: =IFERROR(INDEX(Classifiche!$AB$4:$AB$51,MATCH(1,(Classifiche!$A$4:$A$51="D")*(Classifiche!$L$4:$L$51=1),0)),"") | Y6: 1 | Z6: =IFERROR(INDEX(Classifiche!$B$4:$B$51,MATCH(1,(Classifiche!$A$4:$A$51="E")*(Classifiche!$L$4:$L$51=1),0)),"") | AA6: =IFERROR(INDEX(Classifiche!$I$4:$I$51,MATCH(1,(Classifiche!$A$4:$A$51="E")*(Classifiche!$L$4:$L$51=1),0)),"") | AB6: =IFERROR(INDEX(Classifiche!$AA$4:$AA$51,MATCH(1,(Classifiche!$A$4:$A$51="E")*(Classifiche!$L$4:$L$51=1),0)),"") | AC6: =IFERROR(INDEX(Classifiche!$AB$4:$AB$51,MATCH(1,(Classifiche!$A$4:$A$51="E")*(Classifiche!$L$4:$L$51=1),0)),"") | AE6: 1 | AF6: =IFERROR(INDEX(Classifiche!$B$4:$B$51,MATCH(1,(Classifiche!$A$4:$A$51="F")*(Classifiche!$L$4:$L$51=1),0)),"") | AG6: =IFERROR(INDEX(Classifiche!$I$4:$I$51,MATCH(1,(Classifiche!$A$4:$A$51="F")*(Classifiche!$L$4:$L$51=1),0)),"") | AH6: =IFERROR(INDEX(Classifiche!$AA$4:$AA$51,MATCH(1,(Classifiche!$A$4:$A$51="F")*(Classifiche!$L$4:$L$51=1),0)),"") | AI6: =IFERROR(INDEX(Classifiche!$AB$4:$AB$51,MATCH(1,(Classifiche!$A$4:$A$51="F")*(Classifiche!$L$4:$L$51=1),0)),"") | AN6: =IFERROR(INDEX(Classifiche!$AC$4:$AC$51,MATCH(1,(Classifiche!$A$4:$A$51="A")*(Classifiche!$L$4:$L$51=1),0)),0) | AO6: =IFERROR(INDEX(Classifiche!$AC$4:$AC$51,MATCH(1,(Classifiche!$A$4:$A$51="B")*(Classifiche!$L$4:$L$51=1),0)),0) | AP6: =IFERROR(INDEX(Classifiche!$AC$4:$AC$51,MATCH(1,(Classifiche!$A$4:$A$51="C")*(Classifiche!$L$4:$L$51=1),0)),0) | AQ6: =IFERROR(INDEX(Classifiche!$AC$4:$AC$51,MATCH(1,(Classifiche!$A$4:$A$51="D")*(Classifiche!$L$4:$L$51=1),0)),0) | AR6: =IFERROR(INDEX(Classifiche!$AC$4:$AC$51,MATCH(1,(Classifiche!$A$4:$A$51="E")*(Classifiche!$L$4:$L$51=1),0)),0) | AS6: =IFERROR(INDEX(Classifiche!$AC$4:$AC$51,MATCH(1,(Classifiche!$A$4:$A$51="F")*(Classifiche!$L$4:$L$51=1),0)),0)
A7: 2 | B7: =IFERROR(INDEX(Classifiche!$B$4:$B$51,MATCH(1,(Classifiche!$A$4:$A$51="A")*(Classifiche!$L$4:$L$51=2),0)),"") | C7: =IFERROR(INDEX(Classifiche!$I$4:$I$51,MATCH(1,(Classifiche!$A$4:$A$51="A")*(Classifiche!$L$4:$L$51=2),0)),"") | D7: =IFERROR(INDEX(Classifiche!$AA$4:$AA$51,MATCH(1,(Classifiche!$A$4:$A$51="A")*(Classifiche!$L$4:$L$51=2),0)),"") | E7: =IFERROR(INDEX(Classifiche!$AB$4:$AB$51,MATCH(1,(Classifiche!$A$4:$A$51="A")*(Classifiche!$L$4:$L$51=2),0)),"") | G7: 2 | H7: =IFERROR(INDEX(Classifiche!$B$4:$B$51,MATCH(1,(Classifiche!$A$4:$A$51="B")*(Classifiche!$L$4:$L$51=2),0)),"") | I7: =IFERROR(INDEX(Classifiche!$I$4:$I$51,MATCH(1,(Classifiche!$A$4:$A$51="B")*(Classifiche!$L$4:$L$51=2),0)),"") | J7: =IFERROR(INDEX(Classifiche!$AA$4:$AA$51,MATCH(1,(Classifiche!$A$4:$A$51="B")*(Classifiche!$L$4:$L$51=2),0)),"") | K7: =IFERROR(INDEX(Classifiche!$AB$4:$AB$51,MATCH(1,(Classifiche!$A$4:$A$51="B")*(Classifiche!$L$4:$L$51=2),0)),"") | M7: 2 | N7: =IFERROR(INDEX(Classifiche!$B$4:$B$51,MATCH(1,(Classifiche!$A$4:$A$51="C")*(Classifiche!$L$4:$L$51=2),0)),"") | O7: =IFERROR(INDEX(Classifiche!$I$4:$I$51,MATCH(1,(Classifiche!$A$4:$A$51="C")*(Classifiche!$L$4:$L$51=2),0)),"") | P7: =IFERROR(INDEX(Classifiche!$AA$4:$AA$51,MATCH(1,(Classifiche!$A$4:$A$51="C")*(Classifiche!$L$4:$L$51=2),0)),"") | Q7: =IFERROR(INDEX(Classifiche!$AB$4:$AB$51,MATCH(1,(Classifiche!$A$4:$A$51="C")*(Classifiche!$L$4:$L$51=2),0)),"") | S7: 2 | T7: =IFERROR(INDEX(Classifiche!$B$4:$B$51,MATCH(1,(Classifiche!$A$4:$A$51="D")*(Classifiche!$L$4:$L$51=2),0)),"") | U7: =IFERROR(INDEX(Classifiche!$I$4:$I$51,MATCH(1,(Classifiche!$A$4:$A$51="D")*(Classifiche!$L$4:$L$51=2),0)),"") | V7: =IFERROR(INDEX(Classifiche!$AA$4:$AA$51,MATCH(1,(Classifiche!$A$4:$A$51="D")*(Classifiche!$L$4:$L$51=2),0)),"") | W7: =IFERROR(INDEX(Classifiche!$AB$4:$AB$51,MATCH(1,(Classifiche!$A$4:$A$51="D")*(Classifiche!$L$4:$L$51=2),0)),"") | Y7: 2 | Z7: =IFERROR(INDEX(Classifiche!$B$4:$B$51,MATCH(1,(Classifiche!$A$4:$A$51="E")*(Classifiche!$L$4:$L$51=2),0)),"") | AA7: =IFERROR(INDEX(Classifiche!$I$4:$I$51,MATCH(1,(Classifiche!$A$4:$A$51="E")*(Classifiche!$L$4:$L$51=2),0)),"") | AB7: =IFERROR(INDEX(Classifiche!$AA$4:$AA$51,MATCH(1,(Classifiche!$A$4:$A$51="E")*(Classifiche!$L$4:$L$51=2),0)),"") | AC7: =IFERROR(INDEX(Classifiche!$AB$4:$AB$51,MATCH(1,(Classifiche!$A$4:$A$51="E")*(Classifiche!$L$4:$L$51=2),0)),"") | AE7: 2 | AF7: =IFERROR(INDEX(Classifiche!$B$4:$B$51,MATCH(1,(Classifiche!$A$4:$A$51="F")*(Classifiche!$L$4:$L$51=2),0)),"") | AG7: =IFERROR(INDEX(Classifiche!$I$4:$I$51,MATCH(1,(Classifiche!$A$4:$A$51="F")*(Classifiche!$L$4:$L$51=2),0)),"") | AH7: =IFERROR(INDEX(Classifiche!$AA$4:$AA$51,MATCH(1,(Classifiche!$A$4:$A$51="F")*(Classifiche!$L$4:$L$51=2),0)),"") | AI7: =IFERROR(INDEX(Classifiche!$AB$4:$AB$51,MATCH(1,(Classifiche!$A$4:$A$51="F")*(Classifiche!$L$4:$L$51=2),0)),"") | AN7: =IFERROR(INDEX(Classifiche!$AC$4:$AC$51,MATCH(1,(Classifiche!$A$4:$A$51="A")*(Classifiche!$L$4:$L$51=2),0)),0) | AO7: =IFERROR(INDEX(Classifiche!$AC$4:$AC$51,MATCH(1,(Classifiche!$A$4:$A$51="B")*(Classifiche!$L$4:$L$51=2),0)),0) | AP7: =IFERROR(INDEX(Classifiche!$AC$4:$AC$51,MATCH(1,(Classifiche!$A$4:$A$51="C")*(Classifiche!$L$4:$L$51=2),0)),0) | AQ7: =IFERROR(INDEX(Classifiche!$AC$4:$AC$51,MATCH(1,(Classifiche!$A$4:$A$51="D")*(Classifiche!$L$4:$L$51=2),0)),0) | AR7: =IFERROR(INDEX(Classifiche!$AC$4:$AC$51,MATCH(1,(Classifiche!$A$4:$A$51="E")*(Classifiche!$L$4:$L$51=2),0)),0) | AS7: =IFERROR(INDEX(Classifiche!$AC$4:$AC$51,MATCH(1,(Classifiche!$A$4:$A$51="F")*(Classifiche!$L$4:$L$51=2),0)),0)
A8: 3 | B8: =IFERROR(INDEX(Classifiche!$B$4:$B$51,MATCH(1,(Classifiche!$A$4:$A$51="A")*(Classifiche!$L$4:$L$51=3),0)),"") | C8: =IFERROR(INDEX(Classifiche!$I$4:$I$51,MATCH(1,(Classifiche!$A$4:$A$51="A")*(Classifiche!$L$4:$L$51=3),0)),"") | D8: =IFERROR(INDEX(Classifiche!$AA$4:$AA$51,MATCH(1,(Classifiche!$A$4:$A$51="A")*(Classifiche!$L$4:$L$51=3),0)),"") | E8: =IFERROR(INDEX(Classifiche!$AB$4:$AB$51,MATCH(1,(Classifiche!$A$4:$A$51="A")*(Classifiche!$L$4:$L$51=3),0)),"") | G8: 3 | H8: =IFERROR(INDEX(Classifiche!$B$4:$B$51,MATCH(1,(Classifiche!$A$4:$A$51="B")*(Classifiche!$L$4:$L$51=3),0)),"") | I8: =IFERROR(INDEX(Classifiche!$I$4:$I$51,MATCH(1,(Classifiche!$A$4:$A$51="B")*(Classifiche!$L$4:$L$51=3),0)),"") | J8: =IFERROR(INDEX(Classifiche!$AA$4:$AA$51,MATCH(1,(Classifiche!$A$4:$A$51="B")*(Classifiche!$L$4:$L$51=3),0)),"") | K8: =IFERROR(INDEX(Classifiche!$AB$4:$AB$51,MATCH(1,(Classifiche!$A$4:$A$51="B")*(Classifiche!$L$4:$L$51=3),0)),"") | M8: 3 | N8: =IFERROR(INDEX(Classifiche!$B$4:$B$51,MATCH(1,(Classifiche!$A$4:$A$51="C")*(Classifiche!$L$4:$L$51=3),0)),"") | O8: =IFERROR(INDEX(Classifiche!$I$4:$I$51,MATCH(1,(Classifiche!$A$4:$A$51="C")*(Classifiche!$L$4:$L$51=3),0)),"") | P8: =IFERROR(INDEX(Classifiche!$AA$4:$AA$51,MATCH(1,(Classifiche!$A$4:$A$51="C")*(Classifiche!$L$4:$L$51=3),0)),"") | Q8: =IFERROR(INDEX(Classifiche!$AB$4:$AB$51,MATCH(1,(Classifiche!$A$4:$A$51="C")*(Classifiche!$L$4:$L$51=3),0)),"") | S8: 3 | T8: =IFERROR(INDEX(Classifiche!$B$4:$B$51,MATCH(1,(Classifiche!$A$4:$A$51="D")*(Classifiche!$L$4:$L$51=3),0)),"") | U8: =IFERROR(INDEX(Classifiche!$I$4:$I$51,MATCH(1,(Classifiche!$A$4:$A$51="D")*(Classifiche!$L$4:$L$51=3),0)),"") | V8: =IFERROR(INDEX(Classifiche!$AA$4:$AA$51,MATCH(1,(Classifiche!$A$4:$A$51="D")*(Classifiche!$L$4:$L$51=3),0)),"") | W8: =IFERROR(INDEX(Classifiche!$AB$4:$AB$51,MATCH(1,(Classifiche!$A$4:$A$51="D")*(Classifiche!$L$4:$L$51=3),0)),"") | Y8: 3 | Z8: =IFERROR(INDEX(Classifiche!$B$4:$B$51,MATCH(1,(Classifiche!$A$4:$A$51="E")*(Classifiche!$L$4:$L$51=3),0)),"") | AA8: =IFERROR(INDEX(Classifiche!$I$4:$I$51,MATCH(1,(Classifiche!$A$4:$A$51="E")*(Classifiche!$L$4:$L$51=3),0)),"") | AB8: =IFERROR(INDEX(Classifiche!$AA$4:$AA$51,MATCH(1,(Classifiche!$A$4:$A$51="E")*(Classifiche!$L$4:$L$51=3),0)),"") | AC8: =IFERROR(INDEX(Classifiche!$AB$4:$AB$51,MATCH(1,(Classifiche!$A$4:$A$51="E")*(Classifiche!$L$4:$L$51=3),0)),"") | AE8: 3 | AF8: =IFERROR(INDEX(Classifiche!$B$4:$B$51,MATCH(1,(Classifiche!$A$4:$A$51="F")*(Classifiche!$L$4:$L$51=3),0)),"") | AG8: =IFERROR(INDEX(Classifiche!$I$4:$I$51,MATCH(1,(Classifiche!$A$4:$A$51="F")*(Classifiche!$L$4:$L$51=3),0)),"") | AH8: =IFERROR(INDEX(Classifiche!$AA$4:$AA$51,MATCH(1,(Classifiche!$A$4:$A$51="F")*(Classifiche!$L$4:$L$51=3),0)),"") | AI8: =IFERROR(INDEX(Classifiche!$AB$4:$AB$51,MATCH(1,(Classifiche!$A$4:$A$51="F")*(Classifiche!$L$4:$L$51=3),0)),"") | AN8: =IFERROR(INDEX(Classifiche!$AC$4:$AC$51,MATCH(1,(Classifiche!$A$4:$A$51="A")*(Classifiche!$L$4:$L$51=3),0)),0) | AO8: =IFERROR(INDEX(Classifiche!$AC$4:$AC$51,MATCH(1,(Classifiche!$A$4:$A$51="B")*(Classifiche!$L$4:$L$51=3),0)),0) | AP8: =IFERROR(INDEX(Classifiche!$AC$4:$AC$51,MATCH(1,(Classifiche!$A$4:$A$51="C")*(Classifiche!$L$4:$L$51=3),0)),0) | AQ8: =IFERROR(INDEX(Classifiche!$AC$4:$AC$51,MATCH(1,(Classifiche!$A$4:$A$51="D")*(Classifiche!$L$4:$L$51=3),0)),0) | AR8: =IFERROR(INDEX(Classifiche!$AC$4:$AC$51,MATCH(1,(Classifiche!$A$4:$A$51="E")*(Classifiche!$L$4:$L$51=3),0)),0) | AS8: =IFERROR(INDEX(Classifiche!$AC$4:$AC$51,MATCH(1,(Classifiche!$A$4:$A$51="F")*(Classifiche!$L$4:$L$51=3),0)),0)
A9: 4 | B9: =IFERROR(INDEX(Classifiche!$B$4:$B$51,MATCH(1,(Classifiche!$A$4:$A$51="A")*(Classifiche!$L$4:$L$51=4),0)),"") | C9: =IFERROR(INDEX(Classifiche!$I$4:$I$51,MATCH(1,(Classifiche!$A$4:$A$51="A")*(Classifiche!$L$4:$L$51=4),0)),"") | D9: =IFERROR(INDEX(Classifiche!$AA$4:$AA$51,MATCH(1,(Classifiche!$A$4:$A$51="A")*(Classifiche!$L$4:$L$51=4),0)),"") | E9: =IFERROR(INDEX(Classifiche!$AB$4:$AB$51,MATCH(1,(Classifiche!$A$4:$A$51="A")*(Classifiche!$L$4:$L$51=4),0)),"") | G9: 4 | H9: =IFERROR(INDEX(Classifiche!$B$4:$B$51,MATCH(1,(Classifiche!$A$4:$A$51="B")*(Classifiche!$L$4:$L$51=4),0)),"") | I9: =IFERROR(INDEX(Classifiche!$I$4:$I$51,MATCH(1,(Classifiche!$A$4:$A$51="B")*(Classifiche!$L$4:$L$51=4),0)),"") | J9: =IFERROR(INDEX(Classifiche!$AA$4:$AA$51,MATCH(1,(Classifiche!$A$4:$A$51="B")*(Classifiche!$L$4:$L$51=4),0)),"") | K9: =IFERROR(INDEX(Classifiche!$AB$4:$AB$51,MATCH(1,(Classifiche!$A$4:$A$51="B")*(Classifiche!$L$4:$L$51=4),0)),"") | M9: 4 | N9: =IFERROR(INDEX(Classifiche!$B$4:$B$51,MATCH(1,(Classifiche!$A$4:$A$51="C")*(Classifiche!$L$4:$L$51=4),0)),"") | O9: =IFERROR(INDEX(Classifiche!$I$4:$I$51,MATCH(1,(Classifiche!$A$4:$A$51="C")*(Classifiche!$L$4:$L$51=4),0)),"") | P9: =IFERROR(INDEX(Classifiche!$AA$4:$AA$51,MATCH(1,(Classifiche!$A$4:$A$51="C")*(Classifiche!$L$4:$L$51=4),0)),"") | Q9: =IFERROR(INDEX(Classifiche!$AB$4:$AB$51,MATCH(1,(Classifiche!$A$4:$A$51="C")*(Classifiche!$L$4:$L$51=4),0)),"") | S9: 4 | T9: =IFERROR(INDEX(Classifiche!$B$4:$B$51,MATCH(1,(Classifiche!$A$4:$A$51="D")*(Classifiche!$L$4:$L$51=4),0)),"") | U9: =IFERROR(INDEX(Classifiche!$I$4:$I$51,MATCH(1,(Classifiche!$A$4:$A$51="D")*(Classifiche!$L$4:$L$51=4),0)),"") | V9: =IFERROR(INDEX(Classifiche!$AA$4:$AA$51,MATCH(1,(Classifiche!$A$4:$A$51="D")*(Classifiche!$L$4:$L$51=4),0)),"") | W9: =IFERROR(INDEX(Classifiche!$AB$4:$AB$51,MATCH(1,(Classifiche!$A$4:$A$51="D")*(Classifiche!$L$4:$L$51=4),0)),"") | Y9: 4 | Z9: =IFERROR(INDEX(Classifiche!$B$4:$B$51,MATCH(1,(Classifiche!$A$4:$A$51="E")*(Classifiche!$L$4:$L$51=4),0)),"") | AA9: =IFERROR(INDEX(Classifiche!$I$4:$I$51,MATCH(1,(Classifiche!$A$4:$A$51="E")*(Classifiche!$L$4:$L$51=4),0)),"") | AB9: =IFERROR(INDEX(Classifiche!$AA$4:$AA$51,MATCH(1,(Classifiche!$A$4:$A$51="E")*(Classifiche!$L$4:$L$51=4),0)),"") | AC9: =IFERROR(INDEX(Classifiche!$AB$4:$AB$51,MATCH(1,(Classifiche!$A$4:$A$51="E")*(Classifiche!$L$4:$L$51=4),0)),"") | AE9: 4 | AF9: =IFERROR(INDEX(Classifiche!$B$4:$B$51,MATCH(1,(Classifiche!$A$4:$A$51="F")*(Classifiche!$L$4:$L$51=4),0)),"") | AG9: =IFERROR(INDEX(Classifiche!$I$4:$I$51,MATCH(1,(Classifiche!$A$4:$A$51="F")*(Classifiche!$L$4:$L$51=4),0)),"") | AH9: =IFERROR(INDEX(Classifiche!$AA$4:$AA$51,MATCH(1,(Classifiche!$A$4:$A$51="F")*(Classifiche!$L$4:$L$51=4),0)),"") | AI9: =IFERROR(INDEX(Classifiche!$AB$4:$AB$51,MATCH(1,(Classifiche!$A$4:$A$51="F")*(Classifiche!$L$4:$L$51=4),0)),"") | AN9: =IFERROR(INDEX(Classifiche!$AC$4:$AC$51,MATCH(1,(Classifiche!$A$4:$A$51="A")*(Classifiche!$L$4:$L$51=4),0)),0) | AO9: =IFERROR(INDEX(Classifiche!$AC$4:$AC$51,MATCH(1,(Classifiche!$A$4:$A$51="B")*(Classifiche!$L$4:$L$51=4),0)),0) | AP9: =IFERROR(INDEX(Classifiche!$AC$4:$AC$51,MATCH(1,(Classifiche!$A$4:$A$51="C")*(Classifiche!$L$4:$L$51=4),0)),0) | AQ9: =IFERROR(INDEX(Classifiche!$AC$4:$AC$51,MATCH(1,(Classifiche!$A$4:$A$51="D")*(Classifiche!$L$4:$L$51=4),0)),0) | AR9: =IFERROR(INDEX(Classifiche!$AC$4:$AC$51,MATCH(1,(Classifiche!$A$4:$A$51="E")*(Classifiche!$L$4:$L$51=4),0)),0) | AS9: =IFERROR(INDEX(Classifiche!$AC$4:$AC$51,MATCH(1,(Classifiche!$A$4:$A$51="F")*(Classifiche!$L$4:$L$51=4),0)),0)
A11: GIRONE G | G11: GIRONE H | M11: GIRONE I | S11: GIRONE J | Y11: GIRONE K | AE11: GIRONE L
A12: Pos | B12: Squadra | C12: Pti | D12: Rim | G12: Pos | H12: Squadra | I12: Pti | J12: Rim | M12: Pos | N12: Squadra | O12: Pti | P12: Rim | S12: Pos | T12: Squadra | U12: Pti | V12: Rim | Y12: Pos | Z12: Squadra | AA12: Pti | AB12: Rim | AE12: Pos | AF12: Squadra | AG12: Pti | AH12: Rim
A13: 1 | B13: =IFERROR(INDEX(Classifiche!$B$4:$B$51,MATCH(1,(Classifiche!$A$4:$A$51="G")*(Classifiche!$L$4:$L$51=1),0)),"") | C13: =IFERROR(INDEX(Classifiche!$I$4:$I$51,MATCH(1,(Classifiche!$A$4:$A$51="G")*(Classifiche!$L$4:$L$51=1),0)),"") | D13: =IFERROR(INDEX(Classifiche!$AA$4:$AA$51,MATCH(1,(Classifiche!$A$4:$A$51="G")*(Classifiche!$L$4:$L$51=1),0)),"") | E13: =IFERROR(INDEX(Classifiche!$AB$4:$AB$51,MATCH(1,(Classifiche!$A$4:$A$51="G")*(Classifiche!$L$4:$L$51=1),0)),"") | G13: 1 | H13: =IFERROR(INDEX(Classifiche!$B$4:$B$51,MATCH(1,(Classifiche!$A$4:$A$51="H")*(Classifiche!$L$4:$L$51=1),0)),"") | I13: =IFERROR(INDEX(Classifiche!$I$4:$I$51,MATCH(1,(Classifiche!$A$4:$A$51="H")*(Classifiche!$L$4:$L$51=1),0)),"") | J13: =IFERROR(INDEX(Classifiche!$AA$4:$AA$51,MATCH(1,(Classifiche!$A$4:$A$51="H")*(Classifiche!$L$4:$L$51=1),0)),"") | K13: =IFERROR(INDEX(Classifiche!$AB$4:$AB$51,MATCH(1,(Classifiche!$A$4:$A$51="H")*(Classifiche!$L$4:$L$51=1),0)),"") | M13: 1 | N13: =IFERROR(INDEX(Classifiche!$B$4:$B$51,MATCH(1,(Classifiche!$A$4:$A$51="I")*(Classifiche!$L$4:$L$51=1),0)),"") | O13: =IFERROR(INDEX(Classifiche!$I$4:$I$51,MATCH(1,(Classifiche!$A$4:$A$51="I")*(Classifiche!$L$4:$L$51=1),0)),"") | P13: =IFERROR(INDEX(Classifiche!$AA$4:$AA$51,MATCH(1,(Classifiche!$A$4:$A$51="I")*(Classifiche!$L$4:$L$51=1),0)),"") | Q13: =IFERROR(INDEX(Classifiche!$AB$4:$AB$51,MATCH(1,(Classifiche!$A$4:$A$51="I")*(Classifiche!$L$4:$L$51=1),0)),"") | S13: 1 | T13: =IFERROR(INDEX(Classifiche!$B$4:$B$51,MATCH(1,(Classifiche!$A$4:$A$51="J")*(Classifiche!$L$4:$L$51=1),0)),"") | U13: =IFERROR(INDEX(Classifiche!$I$4:$I$51,MATCH(1,(Classifiche!$A$4:$A$51="J")*(Classifiche!$L$4:$L$51=1),0)),"") | V13: =IFERROR(INDEX(Classifiche!$AA$4:$AA$51,MATCH(1,(Classifiche!$A$4:$A$51="J")*(Classifiche!$L$4:$L$51=1),0)),"") | W13: =IFERROR(INDEX(Classifiche!$AB$4:$AB$51,MATCH(1,(Classifiche!$A$4:$A$51="J")*(Classifiche!$L$4:$L$51=1),0)),"") | Y13: 1 | Z13: =IFERROR(INDEX(Classifiche!$B$4:$B$51,MATCH(1,(Classifiche!$A$4:$A$51="K")*(Classifiche!$L$4:$L$51=1),0)),"") | AA13: =IFERROR(INDEX(Classifiche!$I$4:$I$51,MATCH(1,(Classifiche!$A$4:$A$51="K")*(Classifiche!$L$4:$L$51=1),0)),"") | AB13: =IFERROR(INDEX(Classifiche!$AA$4:$AA$51,MATCH(1,(Classifiche!$A$4:$A$51="K")*(Classifiche!$L$4:$L$51=1),0)),"") | AC13: =IFERROR(INDEX(Classifiche!$AB$4:$AB$51,MATCH(1,(Classifiche!$A$4:$A$51="K")*(Classifiche!$L$4:$L$51=1),0)),"") | AE13: 1 | AF13: =IFERROR(INDEX(Classifiche!$B$4:$B$51,MATCH(1,(Classifiche!$A$4:$A$51="L")*(Classifiche!$L$4:$L$51=1),0)),"") | AG13: =IFERROR(INDEX(Classifiche!$I$4:$I$51,MATCH(1,(Classifiche!$A$4:$A$51="L")*(Classifiche!$L$4:$L$51=1),0)),"") | AH13: =IFERROR(INDEX(Classifiche!$AA$4:$AA$51,MATCH(1,(Classifiche!$A$4:$A$51="L")*(Classifiche!$L$4:$L$51=1),0)),"") | AI13: =IFERROR(INDEX(Classifiche!$AB$4:$AB$51,MATCH(1,(Classifiche!$A$4:$A$51="L")*(Classifiche!$L$4:$L$51=1),0)),"") | AN13: =IFERROR(INDEX(Classifiche!$AC$4:$AC$51,MATCH(1,(Classifiche!$A$4:$A$51="G")*(Classifiche!$L$4:$L$51=1),0)),0) | AO13: =IFERROR(INDEX(Classifiche!$AC$4:$AC$51,MATCH(1,(Classifiche!$A$4:$A$51="H")*(Classifiche!$L$4:$L$51=1),0)),0) | AP13: =IFERROR(INDEX(Classifiche!$AC$4:$AC$51,MATCH(1,(Classifiche!$A$4:$A$51="I")*(Classifiche!$L$4:$L$51=1),0)),0) | AQ13: =IFERROR(INDEX(Classifiche!$AC$4:$AC$51,MATCH(1,(Classifiche!$A$4:$A$51="J")*(Classifiche!$L$4:$L$51=1),0)),0) | AR13: =IFERROR(INDEX(Classifiche!$AC$4:$AC$51,MATCH(1,(Classifiche!$A$4:$A$51="K")*(Classifiche!$L$4:$L$51=1),0)),0) | AS13: =IFERROR(INDEX(Classifiche!$AC$4:$AC$51,MATCH(1,(Classifiche!$A$4:$A$51="L")*(Classifiche!$L$4:$L$51=1),0)),0)
A14: 2 | B14: =IFERROR(INDEX(Classifiche!$B$4:$B$51,MATCH(1,(Classifiche!$A$4:$A$51="G")*(Classifiche!$L$4:$L$51=2),0)),"") | C14: =IFERROR(INDEX(Classifiche!$I$4:$I$51,MATCH(1,(Classifiche!$A$4:$A$51="G")*(Classifiche!$L$4:$L$51=2),0)),"") | D14: =IFERROR(INDEX(Classifiche!$AA$4:$AA$51,MATCH(1,(Classifiche!$A$4:$A$51="G")*(Classifiche!$L$4:$L$51=2),0)),"") | E14: =IFERROR(INDEX(Classifiche!$AB$4:$AB$51,MATCH(1,(Classifiche!$A$4:$A$51="G")*(Classifiche!$L$4:$L$51=2),0)),"") | G14: 2 | H14: =IFERROR(INDEX(Classifiche!$B$4:$B$51,MATCH(1,(Classifiche!$A$4:$A$51="H")*(Classifiche!$L$4:$L$51=2),0)),"") | I14: =IFERROR(INDEX(Classifiche!$I$4:$I$51,MATCH(1,(Classifiche!$A$4:$A$51="H")*(Classifiche!$L$4:$L$51=2),0)),"") | J14: =IFERROR(INDEX(Classifiche!$AA$4:$AA$51,MATCH(1,(Classifiche!$A$4:$A$51="H")*(Classifiche!$L$4:$L$51=2),0)),"") | K14: =IFERROR(INDEX(Classifiche!$AB$4:$AB$51,MATCH(1,(Classifiche!$A$4:$A$51="H")*(Classifiche!$L$4:$L$51=2),0)),"") | M14: 2 | N14: =IFERROR(INDEX(Classifiche!$B$4:$B$51,MATCH(1,(Classifiche!$A$4:$A$51="I")*(Classifiche!$L$4:$L$51=2),0)),"") | O14: =IFERROR(INDEX(Classifiche!$I$4:$I$51,MATCH(1,(Classifiche!$A$4:$A$51="I")*(Classifiche!$L$4:$L$51=2),0)),"") | P14: =IFERROR(INDEX(Classifiche!$AA$4:$AA$51,MATCH(1,(Classifiche!$A$4:$A$51="I")*(Classifiche!$L$4:$L$51=2),0)),"") | Q14: =IFERROR(INDEX(Classifiche!$AB$4:$AB$51,MATCH(1,(Classifiche!$A$4:$A$51="I")*(Classifiche!$L$4:$L$51=2),0)),"") | S14: 2 | T14: =IFERROR(INDEX(Classifiche!$B$4:$B$51,MATCH(1,(Classifiche!$A$4:$A$51="J")*(Classifiche!$L$4:$L$51=2),0)),"") | U14: =IFERROR(INDEX(Classifiche!$I$4:$I$51,MATCH(1,(Classifiche!$A$4:$A$51="J")*(Classifiche!$L$4:$L$51=2),0)),"") | V14: =IFERROR(INDEX(Classifiche!$AA$4:$AA$51,MATCH(1,(Classifiche!$A$4:$A$51="J")*(Classifiche!$L$4:$L$51=2),0)),"") | W14: =IFERROR(INDEX(Classifiche!$AB$4:$AB$51,MATCH(1,(Classifiche!$A$4:$A$51="J")*(Classifiche!$L$4:$L$51=2),0)),"") | Y14: 2 | Z14: =IFERROR(INDEX(Classifiche!$B$4:$B$51,MATCH(1,(Classifiche!$A$4:$A$51="K")*(Classifiche!$L$4:$L$51=2),0)),"") | AA14: =IFERROR(INDEX(Classifiche!$I$4:$I$51,MATCH(1,(Classifiche!$A$4:$A$51="K")*(Classifiche!$L$4:$L$51=2),0)),"") | AB14: =IFERROR(INDEX(Classifiche!$AA$4:$AA$51,MATCH(1,(Classifiche!$A$4:$A$51="K")*(Classifiche!$L$4:$L$51=2),0)),"") | AC14: =IFERROR(INDEX(Classifiche!$AB$4:$AB$51,MATCH(1,(Classifiche!$A$4:$A$51="K")*(Classifiche!$L$4:$L$51=2),0)),"") | AE14: 2 | AF14: =IFERROR(INDEX(Classifiche!$B$4:$B$51,MATCH(1,(Classifiche!$A$4:$A$51="L")*(Classifiche!$L$4:$L$51=2),0)),"") | AG14: =IFERROR(INDEX(Classifiche!$I$4:$I$51,MATCH(1,(Classifiche!$A$4:$A$51="L")*(Classifiche!$L$4:$L$51=2),0)),"") | AH14: =IFERROR(INDEX(Classifiche!$AA$4:$AA$51,MATCH(1,(Classifiche!$A$4:$A$51="L")*(Classifiche!$L$4:$L$51=2),0)),"") | AI14: =IFERROR(INDEX(Classifiche!$AB$4:$AB$51,MATCH(1,(Classifiche!$A$4:$A$51="L")*(Classifiche!$L$4:$L$51=2),0)),"") | AN14: =IFERROR(INDEX(Classifiche!$AC$4:$AC$51,MATCH(1,(Classifiche!$A$4:$A$51="G")*(Classifiche!$L$4:$L$51=2),0)),0) | AO14: =IFERROR(INDEX(Classifiche!$AC$4:$AC$51,MATCH(1,(Classifiche!$A$4:$A$51="H")*(Classifiche!$L$4:$L$51=2),0)),0) | AP14: =IFERROR(INDEX(Classifiche!$AC$4:$AC$51,MATCH(1,(Classifiche!$A$4:$A$51="I")*(Classifiche!$L$4:$L$51=2),0)),0) | AQ14: =IFERROR(INDEX(Classifiche!$AC$4:$AC$51,MATCH(1,(Classifiche!$A$4:$A$51="J")*(Classifiche!$L$4:$L$51=2),0)),0) | AR14: =IFERROR(INDEX(Classifiche!$AC$4:$AC$51,MATCH(1,(Classifiche!$A$4:$A$51="K")*(Classifiche!$L$4:$L$51=2),0)),0) | AS14: =IFERROR(INDEX(Classifiche!$AC$4:$AC$51,MATCH(1,(Classifiche!$A$4:$A$51="L")*(Classifiche!$L$4:$L$51=2),0)),0)
A15: 3 | B15: =IFERROR(INDEX(Classifiche!$B$4:$B$51,MATCH(1,(Classifiche!$A$4:$A$51="G")*(Classifiche!$L$4:$L$51=3),0)),"") | C15: =IFERROR(INDEX(Classifiche!$I$4:$I$51,MATCH(1,(Classifiche!$A$4:$A$51="G")*(Classifiche!$L$4:$L$51=3),0)),"") | D15: =IFERROR(INDEX(Classifiche!$AA$4:$AA$51,MATCH(1,(Classifiche!$A$4:$A$51="G")*(Classifiche!$L$4:$L$51=3),0)),"") | E15: =IFERROR(INDEX(Classifiche!$AB$4:$AB$51,MATCH(1,(Classifiche!$A$4:$A$51="G")*(Classifiche!$L$4:$L$51=3),0)),"") | G15: 3 | H15: =IFERROR(INDEX(Classifiche!$B$4:$B$51,MATCH(1,(Classifiche!$A$4:$A$51="H")*(Classifiche!$L$4:$L$51=3),0)),"") | I15: =IFERROR(INDEX(Classifiche!$I$4:$I$51,MATCH(1,(Classifiche!$A$4:$A$51="H")*(Classifiche!$L$4:$L$51=3),0)),"") | J15: =IFERROR(INDEX(Classifiche!$AA$4:$AA$51,MATCH(1,(Classifiche!$A$4:$A$51="H")*(Classifiche!$L$4:$L$51=3),0)),"") | K15: =IFERROR(INDEX(Classifiche!$AB$4:$AB$51,MATCH(1,(Classifiche!$A$4:$A$51="H")*(Classifiche!$L$4:$L$51=3),0)),"") | M15: 3 | N15: =IFERROR(INDEX(Classifiche!$B$4:$B$51,MATCH(1,(Classifiche!$A$4:$A$51="I")*(Classifiche!$L$4:$L$51=3),0)),"") | O15: =IFERROR(INDEX(Classifiche!$I$4:$I$51,MATCH(1,(Classifiche!$A$4:$A$51="I")*(Classifiche!$L$4:$L$51=3),0)),"") | P15: =IFERROR(INDEX(Classifiche!$AA$4:$AA$51,MATCH(1,(Classifiche!$A$4:$A$51="I")*(Classifiche!$L$4:$L$51=3),0)),"") | Q15: =IFERROR(INDEX(Classifiche!$AB$4:$AB$51,MATCH(1,(Classifiche!$A$4:$A$51="I")*(Classifiche!$L$4:$L$51=3),0)),"") | S15: 3 | T15: =IFERROR(INDEX(Classifiche!$B$4:$B$51,MATCH(1,(Classifiche!$A$4:$A$51="J")*(Classifiche!$L$4:$L$51=3),0)),"") | U15: =IFERROR(INDEX(Classifiche!$I$4:$I$51,MATCH(1,(Classifiche!$A$4:$A$51="J")*(Classifiche!$L$4:$L$51=3),0)),"") | V15: =IFERROR(INDEX(Classifiche!$AA$4:$AA$51,MATCH(1,(Classifiche!$A$4:$A$51="J")*(Classifiche!$L$4:$L$51=3),0)),"") | W15: =IFERROR(INDEX(Classifiche!$AB$4:$AB$51,MATCH(1,(Classifiche!$A$4:$A$51="J")*(Classifiche!$L$4:$L$51=3),0)),"") | Y15: 3 | Z15: =IFERROR(INDEX(Classifiche!$B$4:$B$51,MATCH(1,(Classifiche!$A$4:$A$51="K")*(Classifiche!$L$4:$L$51=3),0)),"") | AA15: =IFERROR(INDEX(Classifiche!$I$4:$I$51,MATCH(1,(Classifiche!$A$4:$A$51="K")*(Classifiche!$L$4:$L$51=3),0)),"") | AB15: =IFERROR(INDEX(Classifiche!$AA$4:$AA$51,MATCH(1,(Classifiche!$A$4:$A$51="K")*(Classifiche!$L$4:$L$51=3),0)),"") | AC15: =IFERROR(INDEX(Classifiche!$AB$4:$AB$51,MATCH(1,(Classifiche!$A$4:$A$51="K")*(Classifiche!$L$4:$L$51=3),0)),"") | AE15: 3 | AF15: =IFERROR(INDEX(Classifiche!$B$4:$B$51,MATCH(1,(Classifiche!$A$4:$A$51="L")*(Classifiche!$L$4:$L$51=3),0)),"") | AG15: =IFERROR(INDEX(Classifiche!$I$4:$I$51,MATCH(1,(Classifiche!$A$4:$A$51="L")*(Classifiche!$L$4:$L$51=3),0)),"") | AH15: =IFERROR(INDEX(Classifiche!$AA$4:$AA$51,MATCH(1,(Classifiche!$A$4:$A$51="L")*(Classifiche!$L$4:$L$51=3),0)),"") | AI15: =IFERROR(INDEX(Classifiche!$AB$4:$AB$51,MATCH(1,(Classifiche!$A$4:$A$51="L")*(Classifiche!$L$4:$L$51=3),0)),"") | AN15: =IFERROR(INDEX(Classifiche!$AC$4:$AC$51,MATCH(1,(Classifiche!$A$4:$A$51="G")*(Classifiche!$L$4:$L$51=3),0)),0) | AO15: =IFERROR(INDEX(Classifiche!$AC$4:$AC$51,MATCH(1,(Classifiche!$A$4:$A$51="H")*(Classifiche!$L$4:$L$51=3),0)),0) | AP15: =IFERROR(INDEX(Classifiche!$AC$4:$AC$51,MATCH(1,(Classifiche!$A$4:$A$51="I")*(Classifiche!$L$4:$L$51=3),0)),0) | AQ15: =IFERROR(INDEX(Classifiche!$AC$4:$AC$51,MATCH(1,(Classifiche!$A$4:$A$51="J")*(Classifiche!$L$4:$L$51=3),0)),0) | AR15: =IFERROR(INDEX(Classifiche!$AC$4:$AC$51,MATCH(1,(Classifiche!$A$4:$A$51="K")*(Classifiche!$L$4:$L$51=3),0)),0) | AS15: =IFERROR(INDEX(Classifiche!$AC$4:$AC$51,MATCH(1,(Classifiche!$A$4:$A$51="L")*(Classifiche!$L$4:$L$51=3),0)),0)
A16: 4 | B16: =IFERROR(INDEX(Classifiche!$B$4:$B$51,MATCH(1,(Classifiche!$A$4:$A$51="G")*(Classifiche!$L$4:$L$51=4),0)),"") | C16: =IFERROR(INDEX(Classifiche!$I$4:$I$51,MATCH(1,(Classifiche!$A$4:$A$51="G")*(Classifiche!$L$4:$L$51=4),0)),"") | D16: =IFERROR(INDEX(Classifiche!$AA$4:$AA$51,MATCH(1,(Classifiche!$A$4:$A$51="G")*(Classifiche!$L$4:$L$51=4),0)),"") | E16: =IFERROR(INDEX(Classifiche!$AB$4:$AB$51,MATCH(1,(Classifiche!$A$4:$A$51="G")*(Classifiche!$L$4:$L$51=4),0)),"") | G16: 4 | H16: =IFERROR(INDEX(Classifiche!$B$4:$B$51,MATCH(1,(Classifiche!$A$4:$A$51="H")*(Classifiche!$L$4:$L$51=4),0)),"") | I16: =IFERROR(INDEX(Classifiche!$I$4:$I$51,MATCH(1,(Classifiche!$A$4:$A$51="H")*(Classifiche!$L$4:$L$51=4),0)),"") | J16: =IFERROR(INDEX(Classifiche!$AA$4:$AA$51,MATCH(1,(Classifiche!$A$4:$A$51="H")*(Classifiche!$L$4:$L$51=4),0)),"") | K16: =IFERROR(INDEX(Classifiche!$AB$4:$AB$51,MATCH(1,(Classifiche!$A$4:$A$51="H")*(Classifiche!$L$4:$L$51=4),0)),"") | M16: 4 | N16: =IFERROR(INDEX(Classifiche!$B$4:$B$51,MATCH(1,(Classifiche!$A$4:$A$51="I")*(Classifiche!$L$4:$L$51=4),0)),"") | O16: =IFERROR(INDEX(Classifiche!$I$4:$I$51,MATCH(1,(Classifiche!$A$4:$A$51="I")*(Classifiche!$L$4:$L$51=4),0)),"") | P16: =IFERROR(INDEX(Classifiche!$AA$4:$AA$51,MATCH(1,(Classifiche!$A$4:$A$51="I")*(Classifiche!$L$4:$L$51=4),0)),"") | Q16: =IFERROR(INDEX(Classifiche!$AB$4:$AB$51,MATCH(1,(Classifiche!$A$4:$A$51="I")*(Classifiche!$L$4:$L$51=4),0)),"") | S16: 4 | T16: =IFERROR(INDEX(Classifiche!$B$4:$B$51,MATCH(1,(Classifiche!$A$4:$A$51="J")*(Classifiche!$L$4:$L$51=4),0)),"") | U16: =IFERROR(INDEX(Classifiche!$I$4:$I$51,MATCH(1,(Classifiche!$A$4:$A$51="J")*(Classifiche!$L$4:$L$51=4),0)),"") | V16: =IFERROR(INDEX(Classifiche!$AA$4:$AA$51,MATCH(1,(Classifiche!$A$4:$A$51="J")*(Classifiche!$L$4:$L$51=4),0)),"") | W16: =IFERROR(INDEX(Classifiche!$AB$4:$AB$51,MATCH(1,(Classifiche!$A$4:$A$51="J")*(Classifiche!$L$4:$L$51=4),0)),"") | Y16: 4 | Z16: =IFERROR(INDEX(Classifiche!$B$4:$B$51,MATCH(1,(Classifiche!$A$4:$A$51="K")*(Classifiche!$L$4:$L$51=4),0)),"") | AA16: =IFERROR(INDEX(Classifiche!$I$4:$I$51,MATCH(1,(Classifiche!$A$4:$A$51="K")*(Classifiche!$L$4:$L$51=4),0)),"") | AB16: =IFERROR(INDEX(Classifiche!$AA$4:$AA$51,MATCH(1,(Classifiche!$A$4:$A$51="K")*(Classifiche!$L$4:$L$51=4),0)),"") | AC16: =IFERROR(INDEX(Classifiche!$AB$4:$AB$51,MATCH(1,(Classifiche!$A$4:$A$51="K")*(Classifiche!$L$4:$L$51=4),0)),"") | AE16: 4 | AF16: =IFERROR(INDEX(Classifiche!$B$4:$B$51,MATCH(1,(Classifiche!$A$4:$A$51="L")*(Classifiche!$L$4:$L$51=4),0)),"") | AG16: =IFERROR(INDEX(Classifiche!$I$4:$I$51,MATCH(1,(Classifiche!$A$4:$A$51="L")*(Classifiche!$L$4:$L$51=4),0)),"") | AH16: =IFERROR(INDEX(Classifiche!$AA$4:$AA$51,MATCH(1,(Classifiche!$A$4:$A$51="L")*(Classifiche!$L$4:$L$51=4),0)),"") | AI16: =IFERROR(INDEX(Classifiche!$AB$4:$AB$51,MATCH(1,(Classifiche!$A$4:$A$51="L")*(Classifiche!$L$4:$L$51=4),0)),"") | AN16: =IFERROR(INDEX(Classifiche!$AC$4:$AC$51,MATCH(1,(Classifiche!$A$4:$A$51="G")*(Classifiche!$L$4:$L$51=4),0)),0) | AO16: =IFERROR(INDEX(Classifiche!$AC$4:$AC$51,MATCH(1,(Classifiche!$A$4:$A$51="H")*(Classifiche!$L$4:$L$51=4),0)),0) | AP16: =IFERROR(INDEX(Classifiche!$AC$4:$AC$51,MATCH(1,(Classifiche!$A$4:$A$51="I")*(Classifiche!$L$4:$L$51=4),0)),0) | AQ16: =IFERROR(INDEX(Classifiche!$AC$4:$AC$51,MATCH(1,(Classifiche!$A$4:$A$51="J")*(Classifiche!$L$4:$L$51=4),0)),0) | AR16: =IFERROR(INDEX(Classifiche!$AC$4:$AC$51,MATCH(1,(Classifiche!$A$4:$A$51="K")*(Classifiche!$L$4:$L$51=4),0)),0) | AS16: =IFERROR(INDEX(Classifiche!$AC$4:$AC$51,MATCH(1,(Classifiche!$A$4:$A$51="L")*(Classifiche!$L$4:$L$51=4),0)),0)

Sheet Scommesse
A1: N. bolletta | B1: Indice | C1: Gruppo | D1: Prima squadra | E1: Seconda squadra | F1: Quota | G1: Pos 1a | H1: Pos 2a | I1: Qual 1a | J1: Qual 2a | K1: Elim 1a | L1: Elim 2a | M1: Girone chiuso | N1: Entrambe | O1: STATO | P1: Definitivo | Q1: _q | R1: _dead | S1: _code
A2: 1 | B2: 1 | C2: C | D2: Brasile | E2: Scozia | F2: 2.25 | G2: =IFERROR(INDEX(Classifiche!$L$4:$L$51,MATCH(D2,Classifiche!$B$4:$B$51,0)),"") | H2: =IFERROR(INDEX(Classifiche!$L$4:$L$51,MATCH(E2,Classifiche!$B$4:$B$51,0)),"") | I2: =IFERROR(INDEX(Classifiche!$M$4:$M$51,MATCH(D2,Classifiche!$B$4:$B$51,0)),FALSE) | J2: =IFERROR(INDEX(Classifiche!$M$4:$M$51,MATCH(E2,Classifiche!$B$4:$B$51,0)),FALSE) | K2: =IFERROR(INDEX(Classifiche!$O$4:$O$51,MATCH(D2,Classifiche!$B$4:$B$51,0)),FALSE) | L2: =IFERROR(INDEX(Classifiche!$O$4:$O$51,MATCH(E2,Classifiche!$B$4:$B$51,0)),FALSE) | M2: =IFERROR(INDEX(Classifiche!$V$4:$V$15,MATCH(C2,Classifiche!$U$4:$U$15,0)),FALSE) | N2: =AND(I2,J2) | O2: =IF(N2,IF(M2,"VINTA (def.)","In vincita"),IF(OR(K2,L2,M2),"PERSA (def.)","In perdita")) | P2: =IF(OR(AND(N2,M2),AND(NOT(N2),OR(K2,L2,M2))),"SI","NO") | Q2: =IF(N2,1,0) | R2: =IF(OR(K2,L2,AND(M2,NOT(N2))),1,0) | S2: =IF(N2,IF(M2,2,1),IF(OR(K2,L2,M2),-2,-1))
A3: 1 | B3: 2 | C3: E | D3: Germania | E3: Ecuador | F3: 1.65 | G3: =IFERROR(INDEX(Classifiche!$L$4:$L$51,MATCH(D3,Classifiche!$B$4:$B$51,0)),"") | H3: =IFERROR(INDEX(Classifiche!$L$4:$L$51,MATCH(E3,Classifiche!$B$4:$B$51,0)),"") | I3: =IFERROR(INDEX(Classifiche!$M$4:$M$51,MATCH(D3,Classifiche!$B$4:$B$51,0)),FALSE) | J3: =IFERROR(INDEX(Classifiche!$M$4:$M$51,MATCH(E3,Classifiche!$B$4:$B$51,0)),FALSE) | K3: =IFERROR(INDEX(Classifiche!$O$4:$O$51,MATCH(D3,Classifiche!$B$4:$B$51,0)),FALSE) | L3: =IFERROR(INDEX(Classifiche!$O$4:$O$51,MATCH(E3,Classifiche!$B$4:$B$51,0)),FALSE) | M3: =IFERROR(INDEX(Classifiche!$V$4:$V$15,MATCH(C3,Classifiche!$U$4:$U$15,0)),FALSE) | N3: =AND(I3,J3) | O3: =IF(N3,IF(M3,"VINTA (def.)","In vincita"),IF(OR(K3,L3,M3),"PERSA (def.)","In perdita")) | P3: =IF(OR(AND(N3,M3),AND(NOT(N3),OR(K3,L3,M3))),"SI","NO") | Q3: =IF(N3,1,0) | R3: =IF(OR(K3,L3,AND(M3,NOT(N3))),1,0) | S3: =IF(N3,IF(M3,2,1),IF(OR(K3,L3,M3),-2,-1))
A4: 1 | B4: 3 | C4: F | D4: Olanda | E4: Giappone | F4: 2.25 | G4: =IFERROR(INDEX(Classifiche!$L$4:$L$51,MATCH(D4,Classifiche!$B$4:$B$51,0)),"") | H4: =IFERROR(INDEX(Classifiche!$L$4:$L$51,MATCH(E4,Classifiche!$B$4:$B$51,0)),"") | I4: =IFERROR(INDEX(Classifiche!$M$4:$M$51,MATCH(D4,Classifiche!$B$4:$B$51,0)),FALSE) | J4: =IFERROR(INDEX(Classifiche!$M$4:$M$51,MATCH(E4,Classifiche!$B$4:$B$51,0)),FALSE) | K4: =IFERROR(INDEX(Classifiche!$O$4:$O$51,MATCH(D4,Classifiche!$B$4:$B$51,0)),FALSE) | L4: =IFERROR(INDEX(Classifiche!$O$4:$O$51,MATCH(E4,Classifiche!$B$4:$B$51,0)),FALSE) | M4: =IFERROR(INDEX(Classifiche!$V$4:$V$15,MATCH(C4,Classifiche!$U$4:$U$15,0)),FALSE) | N4: =AND(I4,J4) | O4: =IF(N4,IF(M4,"VINTA (def.)","In vincita"),IF(OR(K4,L4,M4),"PERSA (def.)","In perdita")) | P4: =IF(OR(AND(N4,M4),AND(NOT(N4),OR(K4,L4,M4))),"SI","NO") | Q4: =IF(N4,1,0) | R4: =IF(OR(K4,L4,AND(M4,NOT(N4))),1,0) | S4: =IF(N4,IF(M4,2,1),IF(OR(K4,L4,M4),-2,-1))
A5: 1 | B5: 4 | C5: F | D5: Olanda | E5: Svezia | F5: 2.75 | G5: =IFERROR(INDEX(Classifiche!$L$4:$L$51,MATCH(D5,Classifiche!$B$4:$B$51,0)),"") | H5: =IFERROR(INDEX(Classifiche!$L$4:$L$51,MATCH(E5,Classifiche!$B$4:$B$51,0)),"") | I5: =IFERROR(INDEX(Classifiche!$M$4:$M$51,MATCH(D5,Classifiche!$B$4:$B$51,0)),FALSE) | J5: =IFERROR(INDEX(Classifiche!$M$4:$M$51,MATCH(E5,Classifiche!$B$4:$B$51,0)),FALSE) | K5: =IFERROR(INDEX(Classifiche!$O$4:$O$51,MATCH(D5,Classifiche!$B$4:$B$51,0)),FALSE) | L5: =IFERROR(INDEX(Classifiche!$O$4:$O$51,MATCH(E5,Classifiche!$B$4:$B$51,0)),FALSE) | M5: =IFERROR(INDEX(Classifiche!$V$4:$V$15,MATCH(C5,Classifiche!$U$4:$U$15,0)),FALSE) | N5: =AND(I5,J5) | O5: =IF(N5,IF(M5,"VINTA (def.)","In vincita"),IF(OR(K5,L5,M5),"PERSA (def.)","In perdita")) | P5: =IF(OR(AND(N5,M5),AND(NOT(N5),OR(K5,L5,M5))),"SI","NO") | Q5: =IF(N5,1,0) | R5: =IF(OR(K5,L5,AND(M5,NOT(N5))),1,0) | S5: =IF(N5,IF(M5,2,1),IF(OR(K5,L5,M5),-2,-1))
